Workbook

Sheet PROJEÇÃO 2025
A1: META ANUAL: R$5.000.000,00 | F1: META | H1: REALIZADO | I1: % REALIZADA | K1: META | M1: REALIZADO | N1: % REALIZADA | P1: META | R1: REALIZADO | S1: % REALIZADA
A2: MESES | B2: FATURAMENTO | C2: META | D2: % META | F2: META FATURAMENTO | G2: 250000 | H2: =JANEIRO!E65 -> 302600 | I2: =H2/G2 -> 1.2104 | K2: META FATURAMENTO | L2: 300000 | M2: =FEVEREIRO!E64 -> 390450 | N2: =M2/L2 -> 1.3015 | P2: META FATURAMENTO | Q2: 350000 | R2: ='MARÇO'!E69 -> 343280 | S2: =R2/Q2 -> 0.9808
A3: JANEIRO | B3: =JANEIRO!E65 -> 302600 | C3: =G2 -> 250000 | D3: =B3/C3 -> 1.2104 | F3: LIGAÇÃO | G3: 110 | H3: 14 | I3: =H3/G3 -> 0.12727273 | K3: LIGAÇÃO | L3: 110 | M3: 22 | N3: =M3/L3 -> 0.2 | P3: LIGAÇÃO | Q3: 110 | R3: 6 | S3: =R3/Q3 -> 0.054545455
A4: FEVEREIRO | B4: =FEVEREIRO!E64 -> 390450 | C4: =L2 -> 300000 | D4: =B4/C4 -> 1.3015 | F4: CARGAS | G4: 50 | H4: 32 | I4: =H4/G4 -> 0.64 | K4: CARGAS | L4: 50 | M4: 40 | N4: =M4/L4 -> 0.8 | P4: CARGAS | Q4: 50 | R4: 43 | S4: =R4/Q4 -> 0.86
A5: MARÇO | B5: ='MARÇO'!E69 -> 343280 | C5: =Q2 -> 350000 | D5: =B5/C5 -> 0.9808 | F5: COMISSÃO | G5: 12000 | H5: 10400 | I5: =H5/G5 -> 0.86666667 | K5: COMISSÃO | L5: 14000 | M5: 14500 | N5: =M5/L5 -> 1.0357143 | P5: COMISSÃO | Q5: 14000 | R5: 13420 | S5: =R5/Q5 -> 0.95857143
A6: ABRIL | B6: =ABRIL!E65 -> 339900 | C6: =G12 -> 300000 | D6: =B6/C6 -> 1.133 | F6: CLIENTES NOVOS | G6: 3 | H6: 1 | I6: =H6/G6 -> 0.33333333 | K6: CLIENTES NOVOS | L6: 3 | M6: 1 | N6: =M6/L6 -> 0.33333333 | P6: CLIENTES NOVOS | Q6: 3 | R6: 1 | S6: =R6/Q6 -> 0.33333333
A7: MAIO | B7: =MAIO!E61 -> 320880 | C7: =L12 -> 350000 | D7: =B7/C7 -> 0.9168 | F7: JANEIRO | K7: FEVEREIRO | P7: MARÇO
A8: JUNHO | B8: =JUNHO!E77 -> 416920 | C8: 350000 | D8: =B8/C8 -> 1.1912
A9: JULHO | B9: =JULHO!E76 -> 353400 | C9: =G22 -> 420000 | D9: =B9/C9 -> 0.84142857
A10: AGOSTO | B10: =AGOSTO!E71 -> 306620 | C10: =L22 -> 420000 | D10: =B10/C10 -> 0.73004762
A11: SETEMBRO | B11: =SETEMBRO!E79 -> 400120 | C11: =Q22 -> 420000 | D11: =B11/C11 -> 0.95266667 | F11: META | H11: REALIZADO | I11: % REALIZADA | K11: META | M11: REALIZADO | N11: % REALIZADA | P11: META | R11: REALIZADO | S11: % REALIZADA
A12: OUTUBRO | B12: =OUTUBRO!E87 -> 401623 | C12: 420000 | D12: =B12/C12 -> 0.95624524 | F12: META FATURAMENTO | G12: 300000 | H12: =ABRIL!E65 -> 339900 | I12: =H12/G12 -> 1.133 | K12: META FATURAMENTO | L12: 350000 | M12: 417190 | N12: =M12/L12 -> 1.1919714 | P12: META FATURAMENTO | Q12: 420000 | R12: 359000 | S12: =R12/Q12 -> 0.8547619
A13: NOVEMBRO | B13: =NOVEMBRO!E87 -> 341975 | C13: 420000 | D13: =B13/C13 -> 0.81422619 | F13: LIGAÇÃO | G13: 110 | H13: 44 | I13: =H13/G13 -> 0.4 | K13: LIGAÇÃO | L13: 110 | M13: 51 | N13: =M13/L13 -> 0.46363636 | P13: LIGAÇÃO | Q13: 110 | R13: 41 | S13: =R13/Q13 -> 0.37272727
A14: DEZEMBRO | B14: =DEZEMBRO!E87 -> 296575 | C14: 325000 | D14: =B14/C14 -> 0.91253846 | F14: CARGAS | G14: 50 | H14: 41 | I14: =H14/G14 -> 0.82 | K14: CARGAS | L14: 50 | M14: 58 | N14: =M14/L14 -> 1.16 | P14: CARGAS | Q14: 50 | R14: 55 | S14: =R14/Q14 -> 1.1
A15: TOTAL: | B15: =SUM(B3:B14) -> 4214343 | C15: =SUM(C3:C14) -> 4325000 | D15: =AVERAGE(D3:D14) -> 0.99507106 | F15: COMISSÃO | G15: 15000 | H15: 13118.32 | I15: =H15/G15 -> 0.87455467 | K15: COMISSÃO | L15: 15000 | M15: 15848.91 | N15: =M15/L15 -> 1.056594 | P15: COMISSÃO | Q15: 15000 | R15: 13095.95 | S15: =R15/Q15 -> 0.87306333
F16: CLIENTES NOVOS | G16: 3 | H16: 0 | I16: =H16/G16 -> 0 | K16: CLIENTES NOVOS | L16: 3 | M16: 1 | N16: =M16/L16 -> 0.33333333 | P16: CLIENTES NOVOS | Q16: 3 | R16: 0 | S16: =R16/Q16 -> 0
F17: ABRIL | K17: JUNHO | P17: JULHO
F21: META | H21: REALIZADO | I21: % REALIZADA | K21: META | M21: REALIZADO | N21: % REALIZADA | P21: META | R21: REALIZADO | S21: % REALIZADA
F22: META FATURAMENTO | G22: 420000 | H22: 310620 | I22: =H22/G22 -> 0.73957143 | K22: META FATURAMENTO | L22: 420000 | M22: 400220 | N22: =M22/L22 -> 0.95290476 | P22: META FATURAMENTO | Q22: 420000 | R22: =B12 -> 401623 | S22: =R22/Q22 -> 0.95624524
F23: LIGAÇÃO | G23: 110 | H23: 44 | I23: =H23/G23 -> 0.4 | K23: LIGAÇÃO | L23: 110 | M23: 24 | N23: =M23/L23 -> 0.21818182 | P23: LIGAÇÃO | Q23: 110 | R23: 14 | S23: =R23/Q23 -> 0.12727273
F24: CARGAS | G24: 50 | H24: 44 | I24: =H24/G24 -> 0.88 | K24: CARGAS | L24: 50 | M24: 61 | N24: =M24/L24 -> 1.22 | P24: CARGAS | Q24: 50 | R24: 60 | S24: =R24/Q24 -> 1.2
F25: COMISSÃO | G25: 15000 | H25: 9881.8 | I25: =H25/G25 -> 0.65878667 | K25: COMISSÃO | L25: 15000 | M25: 13605.51 | N25: =M25/L25 -> 0.907034 | P25: COMISSÃO | Q25: 15000 | R25: 13519.26 | S25: =R25/Q25 -> 0.901284
F26: CLIENTES NOVOS | G26: 3 | H26: 0 | I26: =H26/G26 -> 0 | K26: CLIENTES NOVOS | L26: 3 | M26: 2 | N26: =M26/L26 -> 0.66666667 | P26: CLIENTES NOVOS | Q26: 3 | R26: 0 | S26: =R26/Q26 -> 0
F27: AGOSTO | K27: SETEMBRO | P27: OUTUBRO
F31: META | H31: REALIZADO | I31: % REALIZADA | K31: META | M31: REALIZADO | N31: % REALIZADA
F32: META FATURAMENTO | G32: 420000 | H32: =B13 -> 341975 | I32: =H32/G32 -> 0.81422619 | K32: META FATURAMENTO | L32: 325000 | M32: =B14 -> 296575 | N32: =M32/L32 -> 0.91253846
F33: LIGAÇÃO | G33: 110 | H33: 15 | I33: =H33/G33 -> 0.13636364 | K33: LIGAÇÃO | L33: 180 | M33: 48 | N33: =M33/L33 -> 0.26666667
F34: CARGAS | G34: 50 | H34: 54 | I34: =H34/G34 -> 1.08 | K34: CARGAS | L34: 50 | M34: =DEZEMBRO!M134+DEZEMBRO!M135 -> 27 | N34: =M34/L34 -> 0.54
F35: COMISSÃO | G35: 15000 | H35: 13000 | I35: =H35/G35 -> 0.86666667 | K35: COMISSÃO | L35: 13000 | M35: =DEZEMBRO!F87 -> 12283.703 | N35: =M35/L35 -> 0.94490023
F36: CLIENTES NOVOS | G36: 3 | H36: 1 | I36: =H36/G36 -> 0.33333333 | K36: CLIENTES NOVOS | L36: 3 | M36: 1 | N36: =M36/L36 -> 0.33333333
F37: NOVEMBRO | K37: DEZEMBRO

Sheet FEEDBACK SEMANAL
A1: RELATÓRIO SEMANA (23/04 - 29/04)
A2: INDICADORES | B2: META | C2: RESULTADOS
A3: LIGAÇÕES / 5 | B3: 12 | C3: 12
A4: CARGAS / 5 | B4: 3 | C4: 2
A5: LEADS ADICIONADOS | B5: 10 | C5: 11
A7: PORCENTAGEM META | B7: 1 | C7: ='ABRIL - 2026'!G85 -> 0.86347826
A8: FATURAMENTO | B8: 460000 | C8: ='ABRIL - 2026'!E79 -> 397200
A10: LEADS DECLINADOS | B10: 5
A12: CLIENTE POTENCIAIS | C12: CLIENTE POTENCIAIS NOVOS
A13: VOESTALPINE | C13: DINOPLAST
A14: VIPAL | C14: BRASPLAST
A15: SULPRINT | C15: VIRTUS
A139: REGRA DE 3 - PORCENTUAL FATURAMENTO
A140: 22 | B140: 1
A141: 12 | B141: =A141*B140/A140 -> 0.54545455

Sheet PROJEÇÃO 2026
A1: META ANUAL: R$7.000.000,00 | G1: META | I1: REALIZADO | J1: % REALIZADA | L1: META | N1: REALIZADO | O1: % REALIZADA | Q1: META | S1: REALIZADO | T1: % REALIZADA
A2: MESES | B2: FATURAMENTO | C2: META PESSOAL | D2: META | E2: % META | G2: META FATURAMENTO | H2: ='JANEIRO - 2026'!G93 -> 325000 | I2: =B3 -> 355490 | J2: =I2/H2 -> 1.0938154 | L2: META FATURAMENTO | M2: 400000 | N2: =B4 -> 282310 | O2: =N2/M2 -> 0.705775 | Q2: META FATURAMENTO | R2: 350000 | S2: =B5 -> 450530 | T2: =S2/R2 -> 1.2872286
A3: JANEIRO | B3: ='JANEIRO - 2026'!G98 -> 355490 | C3: 420000 | D3: =H2 -> 325000 | E3: =B3/D3 -> 1.0938154 | G3: LIGAÇÃO | H3: 110 | I3: 38 | J3: =I3/H3 -> 0.34545455 | L3: LIGAÇÃO | M3: 110 | N3: 115 | O3: =N3/M3 -> 1.0454545 | Q3: LIGAÇÃO | R3: 110 | S3: ='MARÇO - 2026'!J151 -> 94 | T3: =S3/R3 -> 0.85454545
A4: FEVEREIRO | B4: ='FEVEREIRO - 2026'!G98 -> 282310 | C4: 420000 | D4: 400000 | E4: =B4/D4 -> 0.705775 | G4: CARGAS | H4: 50 | I4: ='JANEIRO - 2026'!T134+'JANEIRO - 2026'!T135 -> 62 | J4: =I4/H4 -> 1.24 | L4: CARGAS | M4: 50 | N4: ='FEVEREIRO - 2026'!M134+'FEVEREIRO - 2026'!M135 -> 65 | O4: =N4/M4 -> 1.3 | Q4: CARGAS | R4: 50 | S4: ='MARÇO - 2026'!M144+'MARÇO - 2026'!M145 -> 81 | T4: =S4/R4 -> 1.62
A5: MARÇO | B5: ='MARÇO - 2026'!G108 -> 450530 | C5: 420000 | D5: =R2 -> 350000 | E5: =B5/D5 -> 1.2872286 | G5: COMISSÃO | H5: 15000 | I5: ='JANEIRO - 2026'!F87 -> 13387.191 | J5: =I5/H5 -> 0.89247943 | L5: COMISSÃO | M5: 14000 | N5: ='FEVEREIRO - 2026'!F86 -> 11868.619 | O5: =N5/M5 -> 0.84775848 | Q5: COMISSÃO | R5: 14000 | S5: ='MARÇO - 2026'!F97 -> 15813.763 | T5: =S5/R5 -> 1.1295545
A6: ABRIL | B6: ='ABRIL - 2026'!E79 -> 397200 | C6: 420000 | D6: =H12 -> 460000 | E6: =B6/D6 -> 0.86347826 | G6: CLIENTES NOVOS | H6: 3 | I6: 1 | J6: =I6/H6 -> 0.33333333 | L6: CLIENTES NOVOS | M6: 3 | N6: 1 | O6: =N6/M6 -> 0.33333333 | Q6: CLIENTES NOVOS | R6: 3 | S6: 2 | T6: =S6/R6 -> 0.66666667
A7: MAIO | B7: ='MAIO - 2026'!E78 -> 380491 | C7: 420000 | D7: =M12 -> 450000 | E7: =B7/D7 -> 0.84553556 | G7: JANEIRO | L7: FEVEREIRO | Q7: MARÇO
A8: JUNHO | B8: ='JUNHO - 2026'!E79 -> 2910 | C8: 420000 | D8: =M12 -> 450000 | E8: =B8/D8 -> 0.0064666667
A9: JULHO | B9: ='JULHO - 2026'!E80 -> 0 | C9: 420000 | D9: =H22 -> 700000 | E9: =B9/D9 -> 0
A10: AGOSTO | B10: ='AGOSTO - 2026'!E80 -> 0 | C10: 420000 | D10: =M22 -> 700000 | E10: =B10/D10 -> 0
A11: SETEMBRO | B11: ='SETEMBRO - 2026'!E80 -> 0 | C11: 420000 | D11: =R22 -> 750000 | E11: =B11/D11 -> 0 | G11: META | I11: REALIZADO | J11: % REALIZADA | L11: META | N11: REALIZADO | O11: % REALIZADA | Q11: META | S11: REALIZADO | T11: % REALIZADA
A12: OUTUBRO | B12: ='OUTUBRO - 2026'!E80 -> 0 | C12: 420000 | D12: =R22 -> 750000 | E12: =B12/D12 -> 0 | G12: META FATURAMENTO | H12: 460000 | I12: ='ABRIL - 2026'!G89 -> 397200 | J12: =I12/H12 -> 0.86347826 | L12: META FATURAMENTO | M12: 450000 | N12: ='MAIO - 2026'!E78 -> 380491 | O12: =N12/M12 -> 0.84553556 | Q12: META FATURAMENTO | R12: 600000 | S12: ='JUNHO - 2026'!E79 -> 2910 | T12: =S12/R12 -> 0.00485
A13: NOVEMBRO | B13: ='NOVEMBRO - 2026'!E80 -> 0 | C13: 420000 | D13: =H32 -> 700000 | E13: =B13/D13 -> 0 | G13: LIGAÇÃO | H13: 110 | I13: 64 | J13: =I13/H13 -> 0.58181818 | L13: LIGAÇÃO | M13: 110 | N13: 144 | O13: =N13/M13 -> 1.3090909 | Q13: LIGAÇÃO | R13: 110 | S13: ='JUNHO - 2026'!J134 | T13: =S13/R13 -> 0
A14: DEZEMBRO | B14: ='DEZEMBRO - 2026'!E80 -> 0 | C14: 420000 | D14: =M32 -> 600000 | E14: =B14/D14 -> 0 | G14: CARGAS | H14: 50 | I14: 58 | J14: =I14/H14 -> 1.16 | L14: CARGAS | M14: 50 | N14: ='MAIO - 2026'!N126+'MAIO - 2026'!N127 -> 60 | O14: =N14/M14 -> 1.2 | Q14: CARGAS | R14: 50 | S14: ='JUNHO - 2026'!K133 -> 39 | T14: =S14/R14 -> 0.78
A15: TOTAL: | B15: =SUM(B3:B14) -> 1868931 | C15: =SUM(C3:C14) -> 5040000 | D15: =SUM(D3:D14) -> 6635000 | E15: =AVERAGE(E3:E14) -> 0.40019162 | G15: COMISSÃO | H15: 17000 | I15: ='ABRIL - 2026'!F79 -> 10532.041 | J15: =I15/H15 -> 0.61953183 | L15: COMISSÃO | M15: 20000 | N15: ='MAIO - 2026'!F78 -> 16250.473 | O15: =N15/M15 -> 0.81252365 | Q15: COMISSÃO | R15: 25000 | S15: ='JUNHO - 2026'!F79 -> 131.7 | T15: =S15/R15 -> 0.005268
G16: CLIENTES NOVOS | H16: 3 | I16: 2 | J16: =I16/H16 -> 0.66666667 | L16: CLIENTES NOVOS | M16: 3 | N16: 0 | O16: =N16/M16 -> 0 | Q16: CLIENTES NOVOS | R16: 3 | S16: 0 | T16: =S16/R16 -> 0
G17: ABRIL | L17: MAIO | Q17: JUNHO
A19: META | C19: REALIZADO | D19: % REALIZADA
A20: META FATURAMENTO | B20: 325000 | C20: =279475+9900 -> 289375 | D20: =C20/B20 -> 0.89038462
A21: LIGAÇÃO | B21: 110 | C21: 75 | D21: =C21/B21 -> 0.68181818 | G21: META | I21: REALIZADO | J21: % REALIZADA | L21: META | N21: REALIZADO | O21: % REALIZADA | Q21: META | S21: REALIZADO | T21: % REALIZADA
A22: CARGAS | B22: 50 | C22: 49 | D22: =C22/B22 -> 0.98 | G22: META FATURAMENTO | H22: 700000 | I22: ='JULHO - 2026'!E80 -> 0 | J22: =I22/H22 -> 0 | L22: META FATURAMENTO | M22: 700000 | N22: ='AGOSTO - 2026'!E80 -> 0 | O22: =N22/M22 -> 0 | Q22: META FATURAMENTO | R22: 750000 | S22: ='SETEMBRO - 2026'!E80 -> 0 | T22: =S22/R22 -> 0
A23: COMISSÃO | B23: 15000 | C23: 12044.11 | D23: =C23/B23 -> 0.80294067 | G23: LIGAÇÃO | H23: 110 | I23: ='JULHO - 2026'!J134 -> 0 | J23: =I23/H23 -> 0 | L23: LIGAÇÃO | M23: 110 | N23: ='AGOSTO - 2026'!J134 -> 0 | O23: =N23/M23 -> 0 | Q23: LIGAÇÃO | R23: 110 | S23: ='SETEMBRO - 2026'!J134 -> 0 | T23: =S23/R23 -> 0
A24: CLIENTES NOVOS | B24: 3 | C24: 0 | D24: =C24/B24 -> 0 | G24: CARGAS | H24: 50 | I24: ='JULHO - 2026'!M127+'JULHO - 2026'!M128 -> 0 | J24: =I24/H24 -> 0 | L24: CARGAS | M24: 50 | N24: ='AGOSTO - 2026'!M127+'AGOSTO - 2026'!M128 -> 0 | O24: =N24/M24 -> 0 | Q24: CARGAS | R24: 50 | S24: ='SETEMBRO - 2026'!M127+'SETEMBRO - 2026'!M128 -> 0 | T24: =S24/R24 -> 0
A25: DEZEMBRO - 2025 - PARÂMETRO | G25: COMISSÃO | H25: 30000 | I25: ='JULHO - 2026'!F80 -> 0 | J25: =I25/H25 -> 0 | L25: COMISSÃO | M25: 35000 | N25: ='AGOSTO - 2026'!F80 -> 0 | O25: =N25/M25 -> 0 | Q25: COMISSÃO | R25: 38000 | S25: ='SETEMBRO - 2026'!F80 -> 0 | T25: =S25/R25 -> 0
G26: CLIENTES NOVOS | H26: 3 | I26: 0 | J26: =I26/H26 -> 0 | L26: CLIENTES NOVOS | M26: 3 | N26: 0 | O26: =N26/M26 -> 0 | Q26: CLIENTES NOVOS | R26: 3 | S26: 0 | T26: =S26/R26 -> 0
G27: JULHO | L27: AGOSTO | Q27: SETEMBRO
G31: META | I31: REALIZADO | J31: % REALIZADA | L31: META | N31: REALIZADO | O31: % REALIZADA | Q31: META | S31: REALIZADO | T31: % REALIZADA
G32: META FATURAMENTO | H32: 700000 | I32: ='OUTUBRO - 2026'!E80 -> 0 | J32: =I32/H32 -> 0 | L32: META FATURAMENTO | M32: 600000 | N32: ='NOVEMBRO - 2026'!E80 -> 0 | O32: =N32/M32 -> 0 | Q32: META FATURAMENTO | R32: 600000 | S32: ='DEZEMBRO - 2026'!E80 -> 0 | T32: =S32/R32 -> 0
G33: LIGAÇÃO | H33: 110 | I33: ='OUTUBRO - 2026'!J134 -> 0 | J33: =I33/H33 -> 0 | L33: LIGAÇÃO | M33: 180 | N33: ='NOVEMBRO - 2026'!J134 -> 0 | O33: =N33/M33 -> 0 | Q33: LIGAÇÃO | R33: 180 | S33: ='DEZEMBRO - 2026'!J134 -> 0 | T33: =S33/R33 -> 0
G34: CARGAS | H34: 50 | I34: ='OUTUBRO - 2026'!M127+'OUTUBRO - 2026'!M128 -> 0 | J34: =I34/H34 -> 0 | L34: CARGAS | M34: 50 | N34: ='NOVEMBRO - 2026'!M127+'NOVEMBRO - 2026'!M128 -> 0 | O34: =N34/M34 -> 0 | Q34: CARGAS | R34: 50 | S34: ='DEZEMBRO - 2026'!M127+'DEZEMBRO - 2026'!M128 -> 0 | T34: =S34/R34 -> 0
G35: COMISSÃO | H35: 350000 | I35: ='OUTUBRO - 2026'!F80 -> 0 | J35: =I35/H35 -> 0 | L35: COMISSÃO | M35: 35000 | N35: ='NOVEMBRO - 2026'!F80 -> 0 | O35: =N35/M35 -> 0 | Q35: COMISSÃO | R35: 35000 | S35: ='DEZEMBRO - 2026'!F80 -> 0 | T35: =S35/R35 -> 0
G36: CLIENTES NOVOS | H36: 3 | I36: 0 | J36: =I36/H36 -> 0 | L36: CLIENTES NOVOS | M36: 3 | N36: 1 | O36: =N36/M36 -> 0.33333333 | Q36: CLIENTES NOVOS | R36: 3 | S36: 1 | T36: =S36/R36 -> 0.33333333
G37: OUTUBRO | L37: NOVEMBRO | Q37: DEZEMBRO

Sheet JANEIRO - 2026
A1: GODI TRANSPORTES - UNINDO PROPÓSITOS
A3: DATA | B3: CTE | C3: MANIFESTO | D3: ORIGEM | E3: ESTADO | F3: DESTINO | G3: ESTADO | H3: CLIENTE | I3: PAGAMENTO | J3: CONFERENCIA | K3: MOTORISTA | L3: TELEFONE | M3: VALOR MOTORISTA | N3: VALOR EMPRESA | O3: NF | P3: SEGURO | Q3: SEGURO | R3: ICMS | S3: ICMS | T3: C.O | V3: CO | W3: IMPOSTO | X3: IMPOSTO | Y3: BOLETO | Z3: DIA PAG | AA3: TOTAL TAXAS | AB3: VALOR IMPOSTO | AC3: % | AD3: COMISSÕES | AE3: BOLETOS | AF3: LUCRO | AG3: RENTABIL | AH3: FRETE LIQ | AI3: MOVA | AJ3: ADQ TAB | AK3: VALOR
A4: 46024 | B4: 28238 - 28237 | D4: SÃO LEOPOLDO | E4: RS | F4: CAXIAS DO SUL | G4: RS | H4: CYA RUBBER | I4: FINALIZADO | J4: SIM | K4: PEDRO PAULO DOS SANTOS | M4: 1760 | N4: 2980 | O4: 250000 | P4: 0.0003 | Q4: =O4*P4 -> 75 | R4: 0 | S4: =R4*N4 -> 0 | T4: 0.035 | U4: 1 | V4: =T4*N4 -> 104.3 | W4: 0.065 | X4: =N4*W4 -> 193.7 | Y4: =Z4*0.00133 -> 0.01995 | Z4: 15 | AA4: =R4+T4+W4+Y4 -> 0.11995 | AB4: =N4*AA4+AK4 -> 382.781 | AC4: 0.13 | AD4: =(N4-M4)*AC4 -> 158.6 | AE4: =17.5 -> 17.5 | AF4: =N4-M4-Q4-AB4-AD4-AE4 -> 586.119 | AG4: =AF4/N4 -> 0.19668423 | AH4: =N4-AB4-AI4 -> 2537.768 | AI4: =Y4*N4 -> 59.451 | AJ4: 0.0085 | AK4: =AJ4*N4 -> 25.33
A5: 46024 | B5: 6398-6399 | D5: GUARULHOS | E5: SP | F5: SOROCABA | G5: SP | H5: CYA RUBBER | I5: FINALIZADO | J5: SIM | K5: ALAN OLIVEIRADA SILVA | M5: 2060 | N5: 1250 | O5: 50000 | P5: 0.0003 | Q5: =O5*P5 -> 15 | R5: 0.12 | S5: =R5*N5 -> 150 | T5: 0 | U5: 1 | V5: =T5*N5 -> 0 | W5: 0.065 | X5: =N5*W5 -> 81.25 | Y5: =Z5*0.00133 -> 0.01995 | Z5: 15 | AA5: =R5+T5+W5+Y5 -> 0.20495 | AB5: =N5*AA5+AK5 -> 266.8125 | AC5: 0 | AD5: =(N5-M5)*AC5 -> 0 | AE5: =17.5 -> 17.5 | AF5: =N5-M5-Q5-AB5-AD5-AE5 -> -1109.3125 | AG5: =AF5/N5 -> -0.88745 | AH5: =N5-AB5-AI5 -> 958.25 | AI5: =Y5*N5 -> 24.9375 | AJ5: 0.0085 | AK5: =AJ5*N5 -> 10.625
A6: 46027 | B6: 6426 | D6: GUARULHOS | E6: SP | F6: ITAQUAQUECETUBA | G6: SP | H6: CYA RUBBER | I6: FINALIZADO | J6: SIM | K6: RODRIGO DA SILVA | M6: 860 | N6: 1620 | O6: 80000 | P6: 0.0003 | Q6: =O6*P6 -> 24 | R6: 0.12 | S6: =R6*N6 -> 194.4 | T6: 0 | U6: 1 | V6: =T6*N6 -> 0 | W6: 0.065 | X6: =N6*W6 -> 105.3 | Y6: =Z6*0.00133 -> 0.01995 | Z6: 15 | AA6: =R6+T6+W6+Y6 -> 0.20495 | AB6: =N6*AA6+AK6 -> 345.789 | AC6: 0.13 | AD6: =(N6-M6)*AC6 -> 98.8 | AE6: =17.5 -> 17.5 | AF6: =N6-M6-Q6-AB6-AD6-AE6 -> 273.911 | AG6: =AF6/N6 -> 0.16908086 | AH6: =N6-AB6-AI6 -> 1241.892 | AI6: =Y6*N6 -> 32.319 | AJ6: 0.0085 | AK6: =AJ6*N6 -> 13.77
A7: 46028 | B7: 6427 6428 6429 | D7: GUARULHOS | E7: SP | F7: SÃO BERNARDO DO CAMPO | G7: SP | H7: CYA RUBBER | I7: FINALIZADO | J7: SIM | K7: THIAGO RODRIGUES | M7: 1160 | N7: 2390 | O7: 100000 | P7: 0.0003 | Q7: =O7*P7 -> 30 | R7: 0.12 | S7: =R7*N7 -> 286.8 | T7: 0 | U7: 1 | V7: =T7*N7 -> 0 | W7: 0.065 | X7: =N7*W7 -> 155.35 | Y7: =Z7*0.00133 -> 0.01995 | Z7: 15 | AA7: =R7+T7+W7+Y7 -> 0.20495 | AB7: =N7*AA7+AK7 -> 510.1455 | AC7: 0.13 | AD7: =(N7-M7)*AC7 -> 159.9 | AE7: =17.5 -> 17.5 | AF7: =N7-M7-Q7-AB7-AD7-AE7 -> 512.4545 | AG7: =AF7/N7 -> 0.21441611 | AH7: =N7-AB7-AI7 -> 1832.174 | AI7: =Y7*N7 -> 47.6805 | AJ7: 0.0085 | AK7: =AJ7*N7 -> 20.315
A8: 46028 | B8: 6449 6450 | D8: GUARULHOS | E8: SP | F8: GUARULHOS | G8: SP | H8: CYA RUBBER | I8: FINALIZADO | J8: SIM | K8: THIAGO RODRIGUES | M8: 810 | N8: 1490 | O8: 80000 | P8: 0.0003 | Q8: =O8*P8 -> 24 | R8: 0.12 | S8: =R8*N8 -> 178.8 | T8: 0 | U8: 1 | V8: =T8*N8 -> 0 | W8: 0.065 | X8: =N8*W8 -> 96.85 | Y8: =Z8*0.00133 -> 0.01995 | Z8: 15 | AA8: =R8+T8+W8+Y8 -> 0.20495 | AB8: =N8*AA8+AK8 -> 318.0405 | AC8: 0.13 | AD8: =(N8-M8)*AC8 -> 88.4 | AE8: =17.5 -> 17.5 | AF8: =N8-M8-Q8-AB8-AD8-AE8 -> 232.0595 | AG8: =AF8/N8 -> 0.15574463 | AH8: =N8-AB8-AI8 -> 1142.234 | AI8: =Y8*N8 -> 29.7255 | AJ8: 0.0085 | AK8: =AJ8*N8 -> 12.665
A9: 46030 | B9: 6480 6481 6482 | D9: GUARULHOS | E9: SP | F9: SALTO | G9: SP | H9: CYA RUBBER | I9: FINALIZADO | J9: SIM | K9: DAVISON DOS SANTOS | M9: 1460 | N9: 2300 | O9: 50000 | P9: 0.0003 | Q9: =O9*P9 -> 15 | R9: 0.12 | S9: =R9*N9 -> 276 | T9: 0 | U9: 1 | V9: =T9*N9 -> 0 | W9: 0.065 | X9: =N9*W9 -> 149.5 | Y9: =Z9*0.00133 -> 0.01995 | Z9: 15 | AA9: =R9+T9+W9+Y9 -> 0.20495 | AB9: =N9*AA9+AK9 -> 490.935 | AC9: 0.06 | AD9: =(N9-M9)*AC9 -> 50.4 | AE9: =17.5 -> 17.5 | AF9: =N9-M9-Q9-AB9-AD9-AE9 -> 266.165 | AG9: =AF9/N9 -> 0.11572391 | AH9: =N9-AB9-AI9 -> 1763.18 | AI9: =Y9*N9 -> 45.885 | AJ9: 0.0085 | AK9: =AJ9*N9 -> 19.55
A10: 46031 | B10: 6514 | D10: GUARULHOS | E10: SP | F10: SÃO PAULO | G10: SP | H10: CYA RUBBER | I10: FINALIZADO | J10: SIM | K10: DAVISON DOS SANTOS | M10: 810 | N10: 1490 | O10: 50000 | P10: 0.0003 | Q10: =O10*P10 -> 15 | R10: 0.12 | S10: =R10*N10 -> 178.8 | T10: 0 | U10: 1 | V10: =T10*N10 -> 0 | W10: 0.065 | X10: =N10*W10 -> 96.85 | Y10: =Z10*0.00133 -> 0.01995 | Z10: 15 | AA10: =R10+T10+W10+Y10 -> 0.20495 | AB10: =N10*AA10+AK10 -> 318.0405 | AC10: 0.13 | AD10: =(N10-M10)*AC10 -> 88.4 | AE10: =17.5 -> 17.5 | AF10: =N10-M10-Q10-AB10-AD10-AE10 -> 241.0595 | AG10: =AF10/N10 -> 0.1617849 | AH10: =N10-AB10-AI10 -> 1142.234 | AI10: =Y10*N10 -> 29.7255 | AJ10: 0.0085 | AK10: =AJ10*N10 -> 12.665
A11: 46031 | B11: 6528 - 6543 - 6544 | D11: BETIM | E11: MG | F11: MARABA | G11: PA | H11: UNIFORT | I11: FINALIZADO | J11: SIM | K11: LEONARDO SOARES | M11: 18060 | N11: 27900 | O11: 100000 | P11: 0.0003 | Q11: =O11*P11 -> 30 | R11: 0.03 | S11: =R11*N11 -> 837 | T11: 0.035 | U11: 1 | V11: =T11*N11 -> 976.5 | W11: 0.065 | X11: =N11*W11 -> 1813.5 | Y11: =Z11*0.00133 -> 0.01995 | Z11: 15 | AA11: =R11+T11+W11+Y11 -> 0.14995 | AB11: =N11*AA11+AK11 -> 4420.755 | AC11: 0.1 | AD11: =(N11-M11)*AC11 -> 984 | AE11: =17.5 -> 17.5 | AF11: =N11-M11-Q11-AB11-AD11-AE11 -> 4387.745 | AG11: =AF11/N11 -> 0.15726685 | AH11: =N11-AB11-AI11 -> 22922.64 | AI11: =Y11*N11 -> 556.605 | AJ11: 0.0085 | AK11: =AJ11*N11 -> 237.15
A12: 46033 | B12: 6550 6551 6552 6553 | D12: GOIANIA | E12: GO | F12: IMPERATRIZ | G12: MA | H12: UNIFORT | I12: FINALIZADO | J12: SIM | K12: CIRINEU KOHLBECK | M12: 7760 | N12: 12900 | O12: 80000 | P12: 0.0003 | Q12: =O12*P12 -> 24 | R12: 0.03 | S12: =R12*N12 -> 387 | T12: 0.035 | U12: 1 | V12: =T12*N12 -> 451.5 | W12: 0.065 | X12: =N12*W12 -> 838.5 | Y12: =Z12*0.00133 -> 0.01995 | Z12: 15 | AA12: =R12+T12+W12+Y12 -> 0.14995 | AB12: =N12*AA12+AK12 -> 2044.005 | AC12: 0.1 | AD12: =(N12-M12)*AC12 -> 514 | AE12: =17.5 -> 17.5 | AF12: =N12-M12-Q12-AB12-AD12-AE12 -> 2540.495 | AG12: =AF12/N12 -> 0.1969376 | AH12: =N12-AB12-AI12 -> 10598.64 | AI12: =Y12*N12 -> 257.355 | AJ12: 0.0085 | AK12: =AJ12*N12 -> 109.65
A13: 46033 | B13: 6546 6547 6548 6549 | D13: GOIANIA | E13: GO | F13: VARZEA GRANDE | G13: MT | H13: UNIFORT | I13: FINALIZADO | J13: SIM | K13: KENDERSON LUCAS | M13: 5060 | N13: 8200 | O13: 80000 | P13: 0.0003 | Q13: =O13*P13 -> 24 | R13: 0.03 | S13: =R13*N13 -> 246 | T13: 0.035 | U13: 1 | V13: =T13*N13 -> 287 | W13: 0.065 | X13: =N13*W13 -> 533 | Y13: =Z13*0.00133 -> 0.01995 | Z13: 15 | AA13: =R13+T13+W13+Y13 -> 0.14995 | AB13: =N13*AA13+AK13 -> 1299.29 | AC13: 0.1 | AD13: =(N13-M13)*AC13 -> 314 | AE13: =17.5 -> 17.5 | AF13: =N13-M13-Q13-AB13-AD13-AE13 -> 1485.21 | AG13: =AF13/N13 -> 0.18112317 | AH13: =N13-AB13-AI13 -> 6737.12 | AI13: =Y13*N13 -> 163.59 | AJ13: 0.0085 | AK13: =AJ13*N13 -> 69.7
A14: 46034 | B14: 6556 | D14: GUARULHOS | E14: SP | F14: ITAQUAQUECETUBA | G14: SP | H14: CYA RUBBER | I14: FINALIZADO | J14: SIM | K14: JURANDY VIEIRA PAIVA | M14: 710 | N14: 1190 | O14: 50000 | P14: 0.0003 | Q14: =O14*P14 -> 15 | R14: 0.12 | S14: =R14*N14 -> 142.8 | T14: 0 | U14: 1 | V14: =T14*N14 -> 0 | W14: 0.065 | X14: =N14*W14 -> 77.35 | Y14: =Z14*0.00133 -> 0.01995 | Z14: 15 | AA14: =R14+T14+W14+Y14 -> 0.20495 | AB14: =N14*AA14+AK14 -> 254.0055 | AC14: 0.07 | AD14: =(N14-M14)*AC14 -> 33.6 | AE14: =17.5 -> 17.5 | AF14: =N14-M14-Q14-AB14-AD14-AE14 -> 159.8945 | AG14: =AF14/N14 -> 0.13436513 | AH14: =N14-AB14-AI14 -> 912.254 | AI14: =Y14*N14 -> 23.7405 | AJ14: 0.0085 | AK14: =AJ14*N14 -> 10.115
A15: 46034 | B15: 6557 | D15: GUARULHOS | E15: SP | F15: DIADEMA | G15: SP | H15: CYA RUBBER | I15: FINALIZADO | J15: SIM | K15: TADEU CRISTOVAO DA SILVA | M15: 710 | N15: 1250 | O15: 50000 | P15: 0.0003 | Q15: =O15*P15 -> 15 | R15: 0.12 | S15: =R15*N15 -> 150 | T15: 0 | U15: 1 | V15: =T15*N15 -> 0 | W15: 0.065 | X15: =N15*W15 -> 81.25 | Y15: =Z15*0.00133 -> 0.01995 | Z15: 15 | AA15: =R15+T15+W15+Y15 -> 0.20495 | AB15: =N15*AA15+AK15 -> 266.8125 | AC15: 0.09 | AD15: =(N15-M15)*AC15 -> 48.6 | AE15: =17.5 -> 17.5 | AF15: =N15-M15-Q15-AB15-AD15-AE15 -> 192.0875 | AG15: =AF15/N15 -> 0.15367 | AH15: =N15-AB15-AI15 -> 958.25 | AI15: =Y15*N15 -> 24.9375 | AJ15: 0.0085 | AK15: =AJ15*N15 -> 10.625
A16: 46035 | B16: 6598 | D16: GUARULHOS | E16: SP | F16: GUARULHOS | G16: SP | H16: CYA RUBBER | I16: FINALIZADO | J16: SIM | K16: TADEU CRISTOVAO DA SILVA | M16: 660 | N16: 1250 | O16: 50000 | P16: 0.0003 | Q16: =O16*P16 -> 15 | R16: 0.12 | S16: =R16*N16 -> 150 | T16: 0 | U16: 1 | V16: =T16*N16 -> 0 | W16: 0.065 | X16: =N16*W16 -> 81.25 | Y16: =Z16*0.00133 -> 0.01995 | Z16: 15 | AA16: =R16+T16+W16+Y16 -> 0.20495 | AB16: =N16*AA16+AK16 -> 266.8125 | AC16: 0.13 | AD16: =(N16-M16)*AC16 -> 76.7 | AE16: =17.5 -> 17.5 | AF16: =N16-M16-Q16-AB16-AD16-AE16 -> 213.9875 | AG16: =AF16/N16 -> 0.17119 | AH16: =N16-AB16-AI16 -> 958.25 | AI16: =Y16*N16 -> 24.9375 | AJ16: 0.0085 | AK16: =AJ16*N16 -> 10.625
A17: 46035 | B17: 28340 | D17: ITAJAI | E17: SC | F17: BETIM | G17: MG | H17: UNIFORT | I17: FINALIZADO | J17: SIM | K17: ADILSON VASQUES | M17: 9360 | N17: 12900 | O17: 580000 | P17: 0.0003 | Q17: =O17*P17 -> 174 | R17: 0.056 | S17: =R17*N17 -> 722.4 | T17: 0.035 | U17: 1 | V17: =T17*N17 -> 451.5 | W17: 0.065 | X17: =N17*W17 -> 838.5 | Y17: =Z17*0.00133 -> 0.01995 | Z17: 15 | AA17: =R17+T17+W17+Y17 -> 0.17595 | AB17: =N17*AA17+AK17 -> 2379.405 | AC17: 0 | AD17: 300 | AE17: =17.5 -> 17.5 | AF17: =N17-M17-Q17-AB17-AD17-AE17 -> 669.095 | AG17: =AF17/N17 -> 0.051867829 | AH17: =N17-AB17-AI17 -> 10263.24 | AI17: =Y17*N17 -> 257.355 | AJ17: 0.0085 | AK17: =AJ17*N17 -> 109.65
A18: 46035 | B18: 6624 | D18: ROCA SALES | E18: RS | F18: SÃO LEOPOLDO | G18: RS | H18: QUISVI | I18: FINALIZADO | J18: SIM | K18: CHRISTIANO AFFONSO RITT | M18: 1260 | N18: 2450 | O18: 100000 | P18: 0.0003 | Q18: =O18*P18 -> 30 | R18: 0 | S18: =R18*N18 -> 0 | T18: 0.035 | U18: 1 | V18: =T18*N18 -> 85.75 | W18: 0.065 | X18: =N18*W18 -> 159.25 | Y18: =Z18*0.00133 -> 0.01995 | Z18: 15 | AA18: =R18+T18+W18+Y18 -> 0.11995 | AB18: =N18*AA18+AK18 -> 314.7025 | AC18: 0.13 | AD18: =(N18-M18)*AC18 -> 154.7 | AE18: =17.5 -> 17.5 | AF18: =N18-M18-Q18-AB18-AD18-AE18 -> 673.0975 | AG18: =AF18/N18 -> 0.27473367 | AH18: =N18-AB18-AI18 -> 2086.42 | AI18: =Y18*N18 -> 48.8775 | AJ18: 0.0085 | AK18: =AJ18*N18 -> 20.825
A19: 46036 | B19: 28351 | D19: CRAVINHOS | E19: SP | F19: DIADEMA | G19: SP | H19: TERMOPLAST | I19: FINALIZADO | J19: SIM | K19: GUILHERME LEANDRO | M19: 2260 | N19: 3200 | O19: 50000 | P19: 0.0003 | Q19: =O19*P19 -> 15 | R19: 0.12 | S19: =R19*N19 -> 384 | T19: 0 | U19: 1 | V19: =T19*N19 -> 0 | W19: 0.065 | X19: =N19*W19 -> 208 | Y19: =Z19*0.00133 -> 0.01995 | Z19: 15 | AA19: =R19+T19+W19+Y19 -> 0.20495 | AB19: =N19*AA19+AK19 -> 683.04 | AC19: 0.01 | AD19: 200 | AE19: =17.5 -> 17.5 | AF19: =N19-M19-Q19-AB19-AD19-AE19 -> 24.46 | AG19: =AF19/N19 -> 0.00764375 | AH19: =N19-AB19-AI19 -> 2453.12 | AI19: =Y19*N19 -> 63.84 | AJ19: 0.0085 | AK19: =AJ19*N19 -> 27.2
A20: 46036 | B20: 6665-6666-6667- 6668 -6669-6670 | D20: GOIANIA | E20: GO | F20: MARABA | G20: PA | H20: UNIFORT | I20: FINALIZADO | J20: SIM | K20: WILSON PEREIRA DIAS | M20: 7060 | N20: 13900 | O20: 100000 | P20: 0.0003 | Q20: =O20*P20 -> 30 | R20: 0.03 | S20: =R20*N20 -> 417 | T20: 0.035 | U20: 1 | V20: =T20*N20 -> 486.5 | W20: 0.065 | X20: =N20*W20 -> 903.5 | Y20: =Z20*0.00133 -> 0.01995 | Z20: 15 | AA20: =R20+T20+W20+Y20 -> 0.14995 | AB20: =N20*AA20+AK20 -> 2202.455 | AC20: 0.1 | AD20: =(N20-M20)*AC20 -> 684 | AE20: =17.5 -> 17.5 | AF20: =N20-M20-Q20-AB20-AD20-AE20 -> 3906.045 | AG20: =AF20/N20 -> 0.28101043 | AH20: =N20-AB20-AI20 -> 11420.24 | AI20: =Y20*N20 -> 277.305 | AJ20: 0.0085 | AK20: =AJ20*N20 -> 118.15
A21: 46036 | B21: 6674 - 6675 - 6676 - 6677 - 6684 | D21: GOIANIA | E21: GO | F21: VARZEA GRANDE | G21: MT | H21: UNIFORT | I21: FINALIZADO | J21: SIM | K21: FERNANDO CARDOSO | M21: 4560 | N21: 8200 | O21: 100000 | P21: 0.0003 | Q21: =O21*P21 -> 30 | R21: 0.03 | S21: =R21*N21 -> 246 | T21: 0.035 | U21: 1 | V21: =T21*N21 -> 287 | W21: 0.065 | X21: =N21*W21 -> 533 | Y21: =Z21*0.00133 -> 0.01995 | Z21: 15 | AA21: =R21+T21+W21+Y21 -> 0.14995 | AB21: =N21*AA21+AK21 -> 1299.29 | AC21: 0.1 | AD21: =(N21-M21)*AC21 -> 364 | AE21: =17.5 -> 17.5 | AF21: =N21-M21-Q21-AB21-AD21-AE21 -> 1929.21 | AG21: =AF21/N21 -> 0.23526951 | AH21: =N21-AB21-AI21 -> 6737.12 | AI21: =Y21*N21 -> 163.59 | AJ21: 0.0085 | AK21: =AJ21*N21 -> 69.7
A22: 46036 | B22: 6662 - 6660 | D22: VARZEA GRANDE | E22: MT | F22: VILHENA | G22: RO | H22: UNIFORT | I22: FINALIZADO | J22: SIM | K22: FABIANO RODRIGUES | M22: 2660 | N22: 4200 | O22: 17000 | P22: 0.0003 | Q22: =O22*P22 -> 5.1 | R22: 0.03 | S22: =R22*N22 -> 126 | T22: 0.035 | U22: 1 | V22: =T22*N22 -> 147 | W22: 0.065 | X22: =N22*W22 -> 273 | Y22: =Z22*0.00133 -> 0.01995 | Z22: 15 | AA22: =R22+T22+W22+Y22 -> 0.14995 | AB22: =N22*AA22+AK22 -> 665.49 | AC22: 0.1 | AD22: =(N22-M22)*AC22 -> 154 | AE22: =17.5 -> 17.5 | AF22: =N22-M22-Q22-AB22-AD22-AE22 -> 697.91 | AG22: =AF22/N22 -> 0.16616905 | AH22: =N22-AB22-AI22 -> 3450.72 | AI22: =Y22*N22 -> 83.79 | AJ22: 0.0085 | AK22: =AJ22*N22 -> 35.7
A23: 46038 | B23: 6750 | D23: GUARULHOS | E23: SP | F23: ITAQUAQUECETUBA | G23: SP | H23: CYA RUBBER | I23: FINALIZADO | J23: SIM | K23: EDI LAZARO | M23: 810 | N23: 1620 | O23: 50000 | P23: 0.0003 | Q23: =O23*P23 -> 15 | R23: 0.12 | S23: =R23*N23 -> 194.4 | T23: 0 | U23: 1 | V23: =T23*N23 -> 0 | W23: 0.065 | X23: =N23*W23 -> 105.3 | Y23: =Z23*0.00133 -> 0.01995 | Z23: 15 | AA23: =R23+T23+W23+Y23 -> 0.20495 | AB23: =N23*AA23+AK23 -> 345.789 | AC23: 0.13 | AD23: =(N23-M23)*AC23 -> 105.3 | AE23: =17.5 -> 17.5 | AF23: =N23-M23-Q23-AB23-AD23-AE23 -> 326.411 | AG23: =AF23/N23 -> 0.20148827 | AH23: =N23-AB23-AI23 -> 1241.892 | AI23: =Y23*N23 -> 32.319 | AJ23: 0.0085 | AK23: =AJ23*N23 -> 13.77
A24: 46038 | B24: 6748 | D24: GUARULHOS | E24: SP | F24: ITAQUAQUECETUBA | G24: SP | H24: CYA RUBBER | I24: FINALIZADO | J24: SIM | K24: EDI LAZARO | M24: 710 | N24: 1350 | O24: 50000 | P24: 0.0003 | Q24: =O24*P24 -> 15 | R24: 0.12 | S24: =R24*N24 -> 162 | T24: 0 | U24: 1 | V24: =T24*N24 -> 0 | W24: 0.065 | X24: =N24*W24 -> 87.75 | Y24: =Z24*0.00133 -> 0.01995 | Z24: 15 | AA24: =R24+T24+W24+Y24 -> 0.20495 | AB24: =N24*AA24+AK24 -> 288.1575 | AC24: 0.13 | AD24: =(N24-M24)*AC24 -> 83.2 | AE24: =17.5 -> 17.5 | AF24: =N24-M24-Q24-AB24-AD24-AE24 -> 236.1425 | AG24: =AF24/N24 -> 0.17492037 | AH24: =N24-AB24-AI24 -> 1034.91 | AI24: =Y24*N24 -> 26.9325 | AJ24: 0.0085 | AK24: =AJ24*N24 -> 11.475
A25: 46039 | B25: 6812 - 6813 - 6814 - 6815 - 6816 - 6817 | D25: GOIANIA | E25: GO | F25: MARABA | G25: PA | H25: UNIFORT | I25: FINALIZADO | J25: SIM | K25: HEULLER DUARTE | M25: 6500 | N25: 10900 | O25: 150000 | P25: 0.0003 | Q25: =O25*P25 -> 45 | R25: 0.03 | S25: =R25*N25 -> 327 | T25: 0.035 | U25: 1 | V25: =T25*N25 -> 381.5 | W25: 0.065 | X25: =N25*W25 -> 708.5 | Y25: =Z25*0.00133 -> 0.01995 | Z25: 15 | AA25: =R25+T25+W25+Y25 -> 0.14995 | AB25: =N25*AA25+AK25 -> 1727.105 | AC25: 0.1 | AD25: =(N25-M25)*AC25 -> 440 | AE25: =17.5 -> 17.5 | AF25: =N25-M25-Q25-AB25-AD25-AE25 -> 2170.395 | AG25: =AF25/N25 -> 0.19911881 | AH25: =N25-AB25-AI25 -> 8955.44 | AI25: =Y25*N25 -> 217.455 | AJ25: 0.0085 | AK25: =AJ25*N25 -> 92.65
A26: 46039 | B26: 6818-6819-6820-6821 | D26: GOIANIA | E26: GO | F26: VARZEA GRANDE | G26: MT | H26: UNIFORT | I26: FINALIZADO | J26: SIM | K26: PATRICK DE LIMA LOPES | M26: 4560 | N26: 7900 | O26: 100000 | P26: 0.0003 | Q26: =O26*P26 -> 30 | R26: 0.03 | S26: =R26*N26 -> 237 | T26: 0.035 | U26: 1 | V26: =T26*N26 -> 276.5 | W26: 0.065 | X26: =N26*W26 -> 513.5 | Y26: =Z26*0.00133 -> 0.01995 | Z26: 15 | AA26: =R26+T26+W26+Y26 -> 0.14995 | AB26: =N26*AA26+AK26 -> 1251.755 | AC26: 0.1 | AD26: =(N26-M26)*AC26 -> 334 | AE26: =17.5 -> 17.5 | AF26: =N26-M26-Q26-AB26-AD26-AE26 -> 1706.745 | AG26: =AF26/N26 -> 0.21604367 | AH26: =N26-AB26-AI26 -> 6490.64 | AI26: =Y26*N26 -> 157.605 | AJ26: 0.0085 | AK26: =AJ26*N26 -> 67.15
A27: 46041 | B27: 6829 | D27: GUARULHOS | E27: SP | F27: SÃO JOSÉ DOS CAMPOS | G27: SP | H27: CYA RUBBER | I27: FINALIZADO | J27: SIM | K27: AGNALDO | M27: 760 | N27: 1630 | O27: 50000 | P27: 0.0003 | Q27: =O27*P27 -> 15 | R27: 0.12 | S27: =R27*N27 -> 195.6 | T27: 0 | U27: 1 | V27: =T27*N27 -> 0 | W27: 0.065 | X27: =N27*W27 -> 105.95 | Y27: =Z27*0.00133 -> 0.01995 | Z27: 15 | AA27: =R27+T27+W27+Y27 -> 0.20495 | AB27: =N27*AA27+AK27 -> 347.9235 | AC27: 0.13 | AD27: =(N27-M27)*AC27 -> 113.1 | AE27: =17.5 -> 17.5 | AF27: =N27-M27-Q27-AB27-AD27-AE27 -> 376.4765 | AG27: =AF27/N27 -> 0.23096718 | AH27: =N27-AB27-AI27 -> 1249.558 | AI27: =Y27*N27 -> 32.5185 | AJ27: 0.0085 | AK27: =AJ27*N27 -> 13.855
A28: 46042 | B28: 6890 | D28: ARAQUARI | E28: SC | F28: SANTAREM | G28: PA | H28: ARTESHOW | I28: FINALIZADO | J28: SIM | K28: UBIRATAN MENDES | M28: 9660 | N28: 11000 | O28: 100000 | P28: 0.0003 | Q28: =O28*P28 -> 30 | R28: 0.056 | S28: =R28*N28 -> 616 | T28: 0.035 | U28: 1 | V28: =T28*N28 -> 385 | W28: 0.065 | X28: =N28*W28 -> 715 | Y28: =Z28*0.00133 -> 0 | Z28: 0 | AA28: =R28+T28+W28+Y28 -> 0.156 | AB28: =N28*AA28+AK28 -> 1809.5 | AC28: 0 | AD28: =(N28-M28)*AC28 -> 0 | AE28: =17.5 -> 17.5 | AF28: =N28-M28-Q28-AB28-AD28-AE28 -> -517 | AG28: =AF28/N28 -> -0.047 | AH28: =N28-AB28-AI28 -> 9190.5 | AI28: =Y28*N28 -> 0 | AJ28: 0.0085 | AK28: =AJ28*N28 -> 93.5
A29: 46042 | B29: 6888 | D29: GUARULHOS | E29: SP | F29: SAO PAULO | G29: SP | H29: CYA RUBBER | I29: FINALIZADO | J29: SIM | K29: AILTON GOMES | M29: 760 | N29: 1490 | O29: 80000 | R29: 0.12 | T29: 0 | U29: 1 | V29: =T29*N29 -> 0 | W29: 0.065 | X29: =N29*W29 -> 96.85 | Y29: =Z29*0.00133 -> 0.01995 | Z29: 15 | AA29: =R29+T29+W29+Y29 -> 0.20495 | AB29: =N29*AA29+AK29 -> 318.0405 | AC29: 0.13 | AD29: =(N29-M29)*AC29 -> 94.9 | AE29: =17.5 -> 17.5 | AF29: =N29-M29-Q29-AB29-AD29-AE29 -> 299.5595 | AG29: =AF29/N29 -> 0.20104664 | AH29: =N29-AB29-AI29 -> 1142.234 | AI29: =Y29*N29 -> 29.7255 | AJ29: 0.0085 | AK29: =AJ29*N29 -> 12.665
A30: 46042 | B30: 6884 | D30: GUARULHOS | E30: SP | F30: COTIA | G30: SP | H30: CYA RUBBER | I30: FINALIZADO | J30: SIM | K30: FRANCISCO JOSE | M30: 710 | N30: 1300 | O30: 50000 | R30: 0.12 | T30: 0 | U30: 1 | V30: =T30*N30 -> 0 | W30: 0.065 | X30: =N30*W30 -> 84.5 | Y30: =Z30*0.00133 -> 0.01995 | Z30: 15 | AA30: =R30+T30+W30+Y30 -> 0.20495 | AB30: =N30*AA30+AK30 -> 277.485 | AC30: 0.13 | AD30: =(N30-M30)*AC30 -> 76.7 | AE30: =17.5 -> 17.5 | AF30: =N30-M30-Q30-AB30-AD30-AE30 -> 218.315 | AG30: =AF30/N30 -> 0.16793462 | AH30: =N30-AB30-AI30 -> 996.58 | AI30: =Y30*N30 -> 25.935 | AJ30: 0.0085 | AK30: =AJ30*N30 -> 11.05
A31: 46042 | B31: 6909 | D31: ITAJAI | E31: SC | F31: GUARULHOS | G31: SP | H31: CYA RUBBER | I31: FINALIZADO | J31: SIM | K31: RAFAEL DA SILVA | M31: 3810 | N31: 5900 | O31: 50000 | P31: 0.0003 | Q31: =O31*P31 -> 15 | R31: 0.12 | T31: 0 | U31: 1 | V31: =T31*N31 -> 0 | W31: 0.065 | X31: =N31*W31 -> 383.5 | Y31: =Z31*0.00133 -> 0.01995 | Z31: 15 | AA31: =R31+T31+W31+Y31 -> 0.20495 | AB31: =N31*AA31+AK31 -> 1259.355 | AC31: 0.06 | AD31: =(N31-M31)*AC31 -> 125.4 | AE31: =17.5 -> 17.5 | AF31: =N31-M31-Q31-AB31-AD31-AE31 -> 672.745 | AG31: =AF31/N31 -> 0.11402458 | AH31: =N31-AB31-AI31 -> 4522.94 | AI31: =Y31*N31 -> 117.705 | AJ31: 0.0085 | AK31: =AJ31*N31 -> 50.15
A32: 46043 | B32: 6948 - 6949 - 6950 - 6951 - 6952 - 6953 | D32: GOIANIA | E32: GO | F32: MARABA | G32: MA | H32: UNIFORT | I32: FINALIZADO | J32: SIM | K32: CRISTIANO DAS NEVES | M32: 6560 | N32: 12900 | O32: 80000 | P32: 0.0003 | Q32: =O32*P32 -> 24 | R32: 0.03 | S32: =R32*N32 -> 387 | T32: 0.035 | U32: 1 | V32: =T32*N32 -> 451.5 | W32: 0.065 | X32: =N32*W32 -> 838.5 | Y32: =Z32*0.00133 -> 0.01995 | Z32: 15 | AA32: =R32+T32+W32+Y32 -> 0.14995 | AB32: =N32*AA32+AK32 -> 2044.005 | AC32: 0.1 | AD32: =(N32-M32)*AC32 -> 634 | AE32: =17.5 -> 17.5 | AF32: =N32-M32-Q32-AB32-AD32-AE32 -> 3620.495 | AG32: =AF32/N32 -> 0.28065853 | AH32: =N32-AB32-AI32 -> 10598.64 | AI32: =Y32*N32 -> 257.355 | AJ32: 0.0085 | AK32: =AJ32*N32 -> 109.65
A33: 46043 | B33: 6944 - 6945 - 6946 - 6947 | D33: GOIANIA | E33: GO | F33: VARZEA GRANDE | G33: MT | H33: UNIFORT | I33: FINALIZADO | J33: SIM | K33: JOAO WALGNEI | M33: 4560 | N33: 7900 | O33: 80000 | P33: 0.0003 | Q33: =O33*P33 -> 24 | R33: 0.03 | S33: =R33*N33 -> 237 | T33: 0.035 | U33: 1 | V33: =T33*N33 -> 276.5 | W33: 0.065 | X33: =N33*W33 -> 513.5 | Y33: =Z33*0.00133 -> 0.01995 | Z33: 15 | AA33: =R33+T33+W33+Y33 -> 0.14995 | AB33: =N33*AA33+AK33 -> 1251.755 | AC33: 0.1 | AD33: =(N33-M33)*AC33 -> 334 | AE33: =17.5 -> 17.5 | AF33: =N33-M33-Q33-AB33-AD33-AE33 -> 1712.745 | AG33: =AF33/N33 -> 0.21680316 | AH33: =N33-AB33-AI33 -> 6490.64 | AI33: =Y33*N33 -> 157.605 | AJ33: 0.0085 | AK33: =AJ33*N33 -> 67.15
A34: 46043 | B34: 28435 | D34: ITAJAI | E34: SC | F34: BETIM | G34: MG | H34: UNIFORT | I34: FINALIZADO | J34: SIM | K34: FERNANDO EMANOEL | M34: 9560 | N34: 12900 | O34: 350000 | P34: 0.0003 | Q34: =O34*P34 -> 105 | R34: 0.056 | S34: =R34*N34 -> 722.4 | T34: 0.035 | U34: 1 | V34: =T34*N34 -> 451.5 | W34: 0.065 | X34: =N34*W34 -> 838.5 | Y34: =Z34*0.00133 -> 0.01995 | Z34: 15 | AA34: =R34+T34+W34+Y34 -> 0.17595 | AB34: =N34*AA34+AK34 -> 2379.405 | AC34: 0 | AD34: 300 | AE34: =17.5 -> 17.5 | AF34: =N34-M34-Q34-AB34-AD34-AE34 -> 538.095 | AG34: =AF34/N34 -> 0.041712791 | AH34: =N34-AB34-AI34 -> 10263.24 | AI34: =Y34*N34 -> 257.355 | AJ34: 0.0085 | AK34: =AJ34*N34 -> 109.65
A35: 46043 | B35: 6965 | D35: ITAJAI | E35: SC | F35: BETIM | G35: MG | H35: UNIFORT | I35: FINALIZADO | J35: SIM | K35: CRODOALDO FURTADO | M35: 8250 | N35: 13900 | O35: 350000 | P35: 0.0003 | Q35: =O35*P35 -> 105 | R35: 0.056 | S35: =R35*N35 -> 778.4 | T35: 0.035 | U35: 1 | V35: =T35*N35 -> 486.5 | W35: 0.065 | X35: =N35*W35 -> 903.5 | Y35: =Z35*0.00133 -> 0.01995 | Z35: 15 | AA35: =R35+T35+W35+Y35 -> 0.17595 | AB35: =N35*AA35+AK35 -> 2563.855 | AC35: 0.1 | AD35: =(N35-M35)*AC35 -> 565 | AE35: =17.5 -> 17.5 | AF35: =N35-M35-Q35-AB35-AD35-AE35 -> 2398.645 | AG35: =AF35/N35 -> 0.17256439 | AH35: =N35-AB35-AI35 -> 11058.84 | AI35: =Y35*N35 -> 277.305 | AJ35: 0.0085 | AK35: =AJ35*N35 -> 118.15
A36: 46043 | B36: 6914 | D36: GUARULHOS | E36: SP | F36: SALTO | G36: SP | H36: CYA RUBBER | I36: FINALIZADO | J36: SIM | K36: ANDERSON BARBOSA | M36: 1330 | N36: 2100 | O36: 100000 | P36: 0.0003 | Q36: =O36*P36 -> 30 | R36: 0.12 | S36: =R36*N36 -> 252 | T36: 0 | U36: 1 | V36: =T36*N36 -> 0 | W36: 0.065 | X36: =N36*W36 -> 136.5 | Y36: =Z36*0.00133 -> 0.01995 | Z36: 15 | AA36: =R36+T36+W36+Y36 -> 0.20495 | AB36: =N36*AA36+AK36 -> 448.245 | AC36: 0.05 | AD36: =(N36-M36)*AC36 -> 38.5 | AE36: =17.5 -> 17.5 | AF36: =N36-M36-Q36-AB36-AD36-AE36 -> 235.755 | AG36: =AF36/N36 -> 0.11226429 | AH36: =N36-AB36-AI36 -> 1609.86 | AI36: =Y36*N36 -> 41.895 | AJ36: 0.0085 | AK36: =AJ36*N36 -> 17.85
A37: 46043 | B37: 6961 | D37: GUARULHOS | E37: SP | F37: COTIA | G37: SP | H37: CYA RUBBER | I37: FINALIZADO | J37: SIM | K37: MARCELO ANTONIO | M37: 510 | N37: 720 | O37: 20000 | P37: 0.0003 | Q37: =O37*P37 -> 6 | R37: 0.12 | S37: =R37*N37 -> 86.4 | T37: 0 | U37: 1 | V37: =T37*N37 -> 0 | W37: 0.065 | X37: =N37*W37 -> 46.8 | Y37: =Z37*0.00133 -> 0.01995 | Z37: 15 | AA37: =R37+T37+W37+Y37 -> 0.20495 | AB37: =N37*AA37+AK37 -> 153.684 | AC37: 0 | AD37: =(N37-M37)*AC37 -> 0 | AE37: =17.5 -> 17.5 | AF37: =N37-M37-Q37-AB37-AD37-AE37 -> 32.816 | AG37: =AF37/N37 -> 0.045577778 | AH37: =N37-AB37-AI37 -> 551.952 | AI37: =Y37*N37 -> 14.364 | AJ37: 0.0085 | AK37: =AJ37*N37 -> 6.12
A38: 46044 | B38: 6998 - 6999 | D38: GUARULHOS | E38: SP | F38: ITAQUAQUECETUBA | G38: SP | H38: CYA RUBBER | I38: FINALIZADO | J38: SIM | K38: NATAN SANTOS | M38: 860 | N38: 1400 | O38: 50000 | P38: 0.0003 | Q38: =O38*P38 -> 15 | R38: 0.12 | S38: =R38*N38 -> 168 | T38: 0 | U38: 1 | V38: =T38*N38 -> 0 | W38: 0.065 | X38: =N38*W38 -> 91 | Y38: =Z38*0.00133 -> 0.01995 | Z38: 15 | AA38: =R38+T38+W38+Y38 -> 0.20495 | AB38: =N38*AA38+AK38 -> 298.83 | AC38: 0.07 | AD38: =(N38-M38)*AC38 -> 37.8 | AE38: =17.5 -> 17.5 | AF38: =N38-M38-Q38-AB38-AD38-AE38 -> 170.87 | AG38: =AF38/N38 -> 0.12205 | AH38: =N38-AB38-AI38 -> 1073.24 | AI38: =Y38*N38 -> 27.93 | AJ38: 0.0085 | AK38: =AJ38*N38 -> 11.9
A39: 46044 | B39: 7003 | D39: GUARULHOS | E39: SP | F39: GUARULHOS | G39: SP | H39: CYA RUBBER | I39: FINALIZADO | J39: SIM | K39: HUGO SANTIAGO | M39: 460 | N39: 800 | O39: 50000 | P39: 0.0003 | Q39: =O39*P39 -> 15 | R39: 0.12 | S39: =R39*N39 -> 96 | T39: 0 | U39: 1 | V39: =T39*N39 -> 0 | W39: 0.065 | X39: =N39*W39 -> 52 | Y39: =Z39*0.00133 -> 0.01995 | Z39: 15 | AA39: =R39+T39+W39+Y39 -> 0.20495 | AB39: =N39*AA39+AK39 -> 170.76 | AC39: 0.07 | AD39: =(N39-M39)*AC39 -> 23.8 | AE39: =17.5 -> 17.5 | AF39: =N39-M39-Q39-AB39-AD39-AE39 -> 112.94 | AG39: =AF39/N39 -> 0.141175 | AH39: =N39-AB39-AI39 -> 613.28 | AI39: =Y39*N39 -> 15.96 | AJ39: 0.0085 | AK39: =AJ39*N39 -> 6.8
A40: 46045 | B40: 7898 | D40: GUARULHOS | E40: SP | F40: DIADEMA | G40: SP | H40: CYA RUBBER | I40: FINALIZADO | J40: SIM | K40: THIAGO RODRIGUES | M40: 1100 | N40: 800 | O40: 50000 | P40: 0.0003 | Q40: =O40*P40 -> 15 | R40: 0.12 | S40: =R40*N40 -> 96 | T40: 0 | U40: 1 | V40: =T40*N40 -> 0 | W40: 0.065 | X40: =N40*W40 -> 52 | Y40: =Z40*0.00133 -> 0.01995 | Z40: 15 | AA40: =R40+T40+W40+Y40 -> 0.20495 | AB40: =N40*AA40+AK40 -> 170.76 | AC40: 0.07 | AD40: =(N40-M40)*AC40 -> -21 | AE40: =17.5 -> 17.5 | AF40: =N40-M40-Q40-AB40-AD40-AE40 -> -482.26 | AG40: =AF40/N40 -> -0.602825 | AH40: =N40-AB40-AI40 -> 613.28 | AI40: =Y40*N40 -> 15.96 | AJ40: 0.0085 | AK40: =AJ40*N40 -> 6.8
A41: 46045 | B41: 28493 28492 | D41: ITAJAI | E41: SC | F41: BETIM | G41: MG | H41: UNIFORT | I41: FINALIZADO | J41: SIM | K41: ALEXANDRE HENRIQUE | M41: 7760 | N41: 9800 | O41: 20000 | P41: 0.0003 | Q41: =O41*P41 -> 6 | R41: 0.03 | S41: =R41*N41 -> 294 | T41: 0.035 | U41: 1 | V41: =T41*N41 -> 343 | W41: 0.065 | X41: =N41*W41 -> 637 | Y41: =Z41*0.00133 -> 0.01995 | Z41: 15 | AA41: =R41+T41+W41+Y41 -> 0.14995 | AB41: =N41*AA41+AK41 -> 1552.81 | AC41: 0 | AD41: 300 | AE41: =17.5 -> 17.5 | AF41: =N41-M41-Q41-AB41-AD41-AE41 -> 163.69 | AG41: =AF41/N41 -> 0.016703061 | AH41: =N41-AB41-AI41 -> 8051.68 | AI41: =Y41*N41 -> 195.51 | AJ41: 0.0085 | AK41: =AJ41*N41 -> 83.3
...

Sheet FEVEREIRO - 2026
A1: GODI TRANSPORTES - UNINDO PROPÓSITOS
A3: DATA | B3: CTE | C3: MANIFESTO | D3: ORIGEM | E3: ESTADO | F3: DESTINO | G3: ESTADO | H3: CLIENTE | I3: PAGAMENTO | J3: CONFERENCIA | K3: MOTORISTA | L3: TELEFONE | M3: VALOR MOTORISTA | N3: VALOR EMPRESA | O3: NF | P3: SEGURO | Q3: SEGURO | R3: ICMS | S3: ICMS | T3: C.O | V3: CO | W3: IMPOSTO | X3: IMPOSTO | Y3: BOLETO | Z3: DIA PAG | AA3: TOTAL TAXAS | AB3: VALOR IMPOSTO | AC3: % | AD3: COMISSÕES | AE3: BOLETOS | AF3: LUCRO | AG3: RENTABIL | AH3: FRETE LIQ | AI3: MOVA | AJ3: ADQ TAB | AK3: VALOR
A4: 46055 | B4: 8338 | D4: GUARULHOS | E4: SP | F4: SALTO | G4: SP | H4: CYA RUBBER | I4: FINALIZADO | J4: SIM | K4: EMERSON PEREIRA | M4: 1260 | N4: 2100 | O4: 50000 | P4: 0.0003 | Q4: =O4*P4 -> 15 | R4: 0.12 | T4: 0 | U4: 1 | V4: =T4*N4 -> 0 | W4: 0.065 | X4: =N4*W4 -> 136.5 | Y4: =Z4*0.00133 -> 0.01995 | Z4: 15 | AA4: =R4+T4+W4+Y4 -> 0.20495 | AB4: =N4*AA4+AK4 -> 448.245 | AC4: 0.07 | AD4: =(N4-M4)*AC4 -> 58.8 | AE4: =17.5 -> 17.5 | AF4: =N4-M4-Q4-AB4-AD4-AE4 -> 300.455 | AG4: =AF4/N4 -> 0.14307381 | AH4: =N4-AB4-AI4 -> 1609.86 | AI4: =Y4*N4 -> 41.895 | AJ4: 0.0085 | AK4: =AJ4*N4 -> 17.85
A5: 46055 | B5: 8337 | D5: GUARULHOS | E5: SP | F5: GUARAREMA | G5: SP | H5: CYA RUBBER | I5: FINALIZADO | J5: SIM | K5: LEONIDAS CARNEIRO | M5: 960 | N5: 1790 | O5: 50000 | P5: 0.0003 | Q5: =O5*P5 -> 15 | R5: 0.12 | T5: 0 | U5: 1 | V5: =T5*N5 -> 0 | W5: 0.065 | X5: =N5*W5 -> 116.35 | Y5: =Z5*0.00133 -> 0.01995 | Z5: 15 | AA5: =R5+T5+W5+Y5 -> 0.20495 | AB5: =N5*AA5+AK5 -> 382.0755 | AC5: 0.13 | AD5: =(N5-M5)*AC5 -> 107.9 | AE5: =17.5 -> 17.5 | AF5: =N5-M5-Q5-AB5-AD5-AE5 -> 307.5245 | AG5: =AF5/N5 -> 0.1718014 | AH5: =N5-AB5-AI5 -> 1372.214 | AI5: =Y5*N5 -> 35.7105 | AJ5: 0.0085 | AK5: =AJ5*N5 -> 15.215
A6: 46055 | B6: 8359 | D6: GUARULHOS | E6: SP | F6: BRAGANÇA PAULISTA | G6: SP | H6: CYA RUBBER | I6: FINALIZADO | J6: SIM | K6: NATAN SANTOS | M6: 1140 | N6: 1850 | O6: 50000 | P6: 0.0003 | Q6: =O6*P6 -> 15 | R6: 0.12 | T6: 0 | U6: 1 | V6: =T6*N6 -> 0 | W6: 0.065 | X6: =N6*W6 -> 120.25 | Y6: =Z6*0.00133 -> 0.01995 | Z6: 15 | AA6: =R6+T6+W6+Y6 -> 0.20495 | AB6: =N6*AA6+AK6 -> 394.8825 | AC6: 0.07 | AD6: =(N6-M6)*AC6 -> 49.7 | AE6: =17.5 -> 17.5 | AF6: =N6-M6-Q6-AB6-AD6-AE6 -> 232.9175 | AG6: =AF6/N6 -> 0.12590135 | AH6: =N6-AB6-AI6 -> 1418.21 | AI6: =Y6*N6 -> 36.9075 | AJ6: 0.0085 | AK6: =AJ6*N6 -> 15.725
A7: 46055 | B7: 8335 - 8336 | D7: GUARULHOS | E7: SP | F7: ITAQUAQUECETUBA | G7: SP | H7: CYA RUBBER | I7: FINALIZADO | J7: SIM | K7: LEONIDAS CARNEIRO | M7: 1160 | N7: 2970 | O7: 50000 | P7: 0.0003 | Q7: =O7*P7 -> 15 | R7: 0.12 | T7: 0 | U7: 1 | V7: =T7*N7 -> 0 | W7: 0.065 | X7: =N7*W7 -> 193.05 | Y7: =Z7*0.00133 -> 0.01995 | Z7: 15 | AA7: =R7+T7+W7+Y7 -> 0.20495 | AB7: =N7*AA7+AK7 -> 633.9465 | AC7: 0.13 | AD7: =(N7-M7)*AC7 -> 235.3 | AE7: =17.5 -> 17.5 | AF7: =N7-M7-Q7-AB7-AD7-AE7 -> 908.2535 | AG7: =AF7/N7 -> 0.30580926 | AH7: =N7-AB7-AI7 -> 2276.802 | AI7: =Y7*N7 -> 59.2515 | AJ7: 0.0085 | AK7: =AJ7*N7 -> 25.245
A8: 46055 | B8: 8329 | D8: SÃO LEOPOLDO | E8: RS | F8: NOVA PETROPOLIS | G8: RS | H8: CYA RUBBER | I8: FINALIZADO | J8: SIM | K8: LEONARDO POHLMANN | M8: 1310 | N8: 1400 | O8: 50000 | P8: 0.0003 | Q8: =O8*P8 -> 15 | R8: 0 | T8: 0 | U8: 1 | V8: =T8*N8 -> 0 | W8: 0.065 | X8: =N8*W8 -> 91 | Y8: =Z8*0.00133 -> 0.01995 | Z8: 15 | AA8: =R8+T8+W8+Y8 -> 0.08495 | AB8: =N8*AA8+AK8 -> 130.83 | AC8: 0 | AD8: =(N8-M8)*AC8 -> 0 | AE8: =17.5 -> 17.5 | AF8: =N8-M8-Q8-AB8-AD8-AE8 -> -73.33 | AG8: =AF8/N8 -> -0.052378571 | AH8: =N8-AB8-AI8 -> 1241.24 | AI8: =Y8*N8 -> 27.93 | AJ8: 0.0085 | AK8: =AJ8*N8 -> 11.9
A9: 46055 | B9: 8339 - 8340 - 8341 - 8346 - 8350 - 8348 | D9: GOIANIA | E9: GO | F9: MARABA | G9: PA | H9: UNIFORT | I9: FINALIZADO | J9: SIM | K9: JOAO BELEM | M9: 7660 | N9: 13900 | O9: 100000 | P9: 0.0003 | Q9: =O9*P9 -> 30 | R9: 0.03 | T9: 0.035 | U9: 1 | V9: =T9*N9 -> 486.5 | W9: 0.065 | X9: =N9*W9 -> 903.5 | Y9: =Z9*0.00133 -> 0.01995 | Z9: 15 | AA9: =R9+T9+W9+Y9 -> 0.14995 | AB9: =N9*AA9+AK9 -> 2202.455 | AC9: 0.1 | AD9: =(N9-M9)*AC9 -> 624 | AE9: =17.5 -> 17.5 | AF9: =N9-M9-Q9-AB9-AD9-AE9 -> 3366.045 | AG9: =AF9/N9 -> 0.24216151 | AH9: =N9-AB9-AI9 -> 11420.24 | AI9: =Y9*N9 -> 277.305 | AJ9: 0.0085 | AK9: =AJ9*N9 -> 118.15
A10: 46056 | B10: 8411 | D10: SÃO LEOPOLDO | E10: RS | F10: ROCA SALES | G10: RS | H10: CYA RUBBER | I10: FINALIZADO | J10: SIM | K10: VILMAR ANDRE DOS SANTOS | M10: 1860 | N10: 2250 | O10: 50000 | P10: 0.0003 | Q10: =O10*P10 -> 15 | R10: 0 | T10: 0.035 | U10: 1 | V10: =T10*N10 -> 78.75 | W10: 0.065 | X10: =N10*W10 -> 146.25 | Y10: =Z10*0.00133 -> 0.01995 | Z10: 15 | AA10: =R10+T10+W10+Y10 -> 0.11995 | AB10: =N10*AA10+AK10 -> 289.0125 | AC10: 0 | AD10: =(N10-M10)*AC10 -> 0 | AE10: =17.5 -> 17.5 | AF10: =N10-M10-Q10-AB10-AD10-AE10 -> 68.4875 | AG10: =AF10/N10 -> 0.030438889 | AH10: =N10-AB10-AI10 -> 1916.1 | AI10: =Y10*N10 -> 44.8875 | AJ10: 0.0085 | AK10: =AJ10*N10 -> 19.125
A11: 46056 | B11: 8423 | D11: GUARULHOS | E11: SP | F11: SAO PAULO | G11: SP | H11: CYA RUBBER | I11: FINALIZADO | J11: SIM | K11: LEANDRO ALVES | M11: 560 | N11: 1100 | O11: 50000 | P11: 0.0003 | Q11: =O11*P11 -> 15 | R11: 0.12 | T11: 0 | U11: 1 | V11: =T11*N11 -> 0 | W11: 0.065 | X11: =N11*W11 -> 71.5 | Y11: =Z11*0.00133 -> 0.01995 | Z11: 15 | AA11: =R11+T11+W11+Y11 -> 0.20495 | AB11: =N11*AA11+AK11 -> 234.795 | AC11: 0.13 | AD11: =(N11-M11)*AC11 -> 70.2 | AE11: =17.5 -> 17.5 | AF11: =N11-M11-Q11-AB11-AD11-AE11 -> 202.505 | AG11: =AF11/N11 -> 0.18409545 | AH11: =N11-AB11-AI11 -> 843.26 | AI11: =Y11*N11 -> 21.945 | AJ11: 0.0085 | AK11: =AJ11*N11 -> 9.35
A12: 46057 | B12: 8466 | D12: GUARULHOS | E12: SP | F12: ITAQUAQUECETUBA | G12: SP | H12: CYA RUBBER | I12: FINALIZADO | J12: SIM | K12: EDIVALDO DA SILVA | M12: 460 | N12: 980 | O12: 20000 | P12: 0.0003 | Q12: =O12*P12 -> 6 | R12: 0.12 | T12: 0 | U12: 1 | V12: =T12*N12 -> 0 | W12: 0.065 | X12: =N12*W12 -> 63.7 | Y12: =Z12*0.00133 -> 0.01995 | Z12: 15 | AA12: =R12+T12+W12+Y12 -> 0.20495 | AB12: =N12*AA12+AK12 -> 209.181 | AC12: 0.13 | AD12: =(N12-M12)*AC12 -> 67.6 | AE12: =17.5 -> 17.5 | AF12: =N12-M12-Q12-AB12-AD12-AE12 -> 219.719 | AG12: =AF12/N12 -> 0.22420306 | AH12: =N12-AB12-AI12 -> 751.268 | AI12: =Y12*N12 -> 19.551 | AJ12: 0.0085 | AK12: =AJ12*N12 -> 8.33
A13: 46057 | B13: 8465 | D13: GUARULHOS | E13: SP | F13: SAO JOSE DOS CAMPOS | G13: SP | H13: CYA RUBBER | I13: FINALIZADO | J13: SIM | K13: EDIVALDO DA SILVA | M13: 880 | N13: 1680 | O13: 50000 | P13: 0.0003 | Q13: =O13*P13 -> 15 | R13: 0.12 | T13: 0 | U13: 1 | V13: =T13*N13 -> 0 | W13: 0.065 | X13: =N13*W13 -> 109.2 | Y13: =Z13*0.00133 -> 0.01995 | Z13: 15 | AA13: =R13+T13+W13+Y13 -> 0.20495 | AB13: =N13*AA13+AK13 -> 358.596 | AC13: 0.13 | AD13: =(N13-M13)*AC13 -> 104 | AE13: =17.5 -> 17.5 | AF13: =N13-M13-Q13-AB13-AD13-AE13 -> 304.904 | AG13: =AF13/N13 -> 0.18149048 | AH13: =N13-AB13-AI13 -> 1287.888 | AI13: =Y13*N13 -> 33.516 | AJ13: 0.0085 | AK13: =AJ13*N13 -> 14.28
A14: 46057 | B14: 8427 | D14: GUARULHOS | E14: SP | F14: DIADEMA | G14: SP | H14: CYA RUBBER | I14: FINALIZADO | J14: SIM | K14: FERNANDO DOS SANTOS | M14: 660 | N14: 1200 | O14: 50000 | P14: 0.0003 | Q14: =O14*P14 -> 15 | R14: 0.12 | T14: 0 | U14: 1 | V14: =T14*N14 -> 0 | W14: 0.065 | X14: =N14*W14 -> 78 | Y14: =Z14*0.00133 -> 0.01995 | Z14: 15 | AA14: =R14+T14+W14+Y14 -> 0.20495 | AB14: =N14*AA14+AK14 -> 256.14 | AC14: 0.13 | AD14: =(N14-M14)*AC14 -> 70.2 | AE14: =17.5 -> 17.5 | AF14: =N14-M14-Q14-AB14-AD14-AE14 -> 181.16 | AG14: =AF14/N14 -> 0.15096667 | AH14: =N14-AB14-AI14 -> 919.92 | AI14: =Y14*N14 -> 23.94 | AJ14: 0.0085 | AK14: =AJ14*N14 -> 10.2
A15: 46057 | B15: 8490 8491 | D15: IMPERATRIZ | E15: MA | F15: TERESINA | G15: PI | H15: UNIFORT | I15: FINALIZADO | J15: SIM | K15: AECIO VIEIRA | M15: 2860 | N15: 5800 | O15: 80000 | P15: 0.0003 | Q15: =O15*P15 -> 24 | R15: 0.03 | T15: 0.035 | U15: 1 | V15: =T15*N15 -> 203 | W15: 0.065 | X15: =N15*W15 -> 377 | Y15: =Z15*0.00133 -> 0.01995 | Z15: 15 | AA15: =R15+T15+W15+Y15 -> 0.14995 | AB15: =N15*AA15+AK15 -> 919.01 | AC15: 0.1 | AD15: =(N15-M15)*AC15 -> 294 | AE15: =17.5 -> 17.5 | AF15: =N15-M15-Q15-AB15-AD15-AE15 -> 1685.49 | AG15: =AF15/N15 -> 0.29060172 | AH15: =N15-AB15-AI15 -> 4765.28 | AI15: =Y15*N15 -> 115.71 | AJ15: 0.0085 | AK15: =AJ15*N15 -> 49.3
A16: 46057 | B16: 8479 - 8480 - 8481 - 8483 | D16: GOIANIA | E16: GO | F16: VARZEA GRANDE | G16: MT | H16: UNIFORT | I16: FINALIZADO | J16: SIM | K16: JOAO PEREIRA | M16: 3960 | N16: 6900 | O16: 80000 | P16: 0.0003 | Q16: =O16*P16 -> 24 | R16: 0.03 | T16: 0.035 | U16: 1 | V16: =T16*N16 -> 241.5 | W16: 0.065 | X16: =N16*W16 -> 448.5 | Y16: =Z16*0.00133 -> 0.01995 | Z16: 15 | AA16: =R16+T16+W16+Y16 -> 0.14995 | AB16: =N16*AA16+AK16 -> 1093.305 | AC16: 0.1 | AD16: =(N16-M16)*AC16 -> 294 | AE16: =17.5 -> 17.5 | AF16: =N16-M16-Q16-AB16-AD16-AE16 -> 1511.195 | AG16: =AF16/N16 -> 0.21901377 | AH16: =N16-AB16-AI16 -> 5669.04 | AI16: =Y16*N16 -> 137.655 | AJ16: 0.0085 | AK16: =AJ16*N16 -> 58.65
A17: 46058 | B17: 8504 8505 8506 8507 8508 8509 | D17: GOIANIA | E17: GO | F17: MARABA | G17: PA | H17: UNIFORT | I17: FINALIZADO | J17: SIM | K17: NEUDSON FERREIRA | M17: 6310 | N17: 10900 | O17: 100000 | P17: 0.0003 | Q17: =O17*P17 -> 30 | R17: 0.03 | T17: 0.035 | U17: 1 | V17: =T17*N17 -> 381.5 | W17: 0.065 | X17: =N17*W17 -> 708.5 | Y17: =Z17*0.00133 -> 0.01995 | Z17: 15 | AA17: =R17+T17+W17+Y17 -> 0.14995 | AB17: =N17*AA17+AK17 -> 1727.105 | AC17: 0.1 | AD17: =(N17-M17)*AC17 -> 459 | AE17: =17.5 -> 17.5 | AF17: =N17-M17-Q17-AB17-AD17-AE17 -> 2356.395 | AG17: =AF17/N17 -> 0.21618303 | AH17: =N17-AB17-AI17 -> 8955.44 | AI17: =Y17*N17 -> 217.455 | AJ17: 0.0085 | AK17: =AJ17*N17 -> 92.65
A18: 46058 | B18: 8519 | D18: GUARULHOS | E18: SP | F18: GUARULHOS | G18: SP | H18: CYA RUBBER | I18: FINALIZADO | J18: SIM | K18: LEANDRO ALVES | M18: 560 | N18: 1100 | O18: 20000 | P18: 0.0003 | Q18: =O18*P18 -> 6 | R18: 0.12 | T18: 0 | U18: 1 | V18: =T18*N18 -> 0 | W18: 0.065 | X18: =N18*W18 -> 71.5 | Y18: =Z18*0.00133 -> 0.01995 | Z18: 15 | AA18: =R18+T18+W18+Y18 -> 0.20495 | AB18: =N18*AA18+AK18 -> 234.795 | AC18: 0.13 | AD18: =(N18-M18)*AC18 -> 70.2 | AE18: =17.5 -> 17.5 | AF18: =N18-M18-Q18-AB18-AD18-AE18 -> 211.505 | AG18: =AF18/N18 -> 0.19227727 | AH18: =N18-AB18-AI18 -> 843.26 | AI18: =Y18*N18 -> 21.945 | AJ18: 0.0085 | AK18: =AJ18*N18 -> 9.35
A19: 46058 | B19: 8527 - 8528 | D19: VARZEA GRANDE | E19: MT | F19: VILHENA | G19: RO | H19: UNIFORT | I19: FINALIZADO | J19: SIM | K19: FABIANO RODRIGUES | M19: 3260 | N19: 6500 | O19: 50000 | P19: 0.0003 | Q19: =O19*P19 -> 15 | R19: 0.03 | T19: 0.035 | U19: 1 | V19: =T19*N19 -> 227.5 | W19: 0.065 | X19: =N19*W19 -> 422.5 | Y19: =Z19*0.00133 -> 0.01995 | Z19: 15 | AA19: =R19+T19+W19+Y19 -> 0.14995 | AB19: =N19*AA19+AK19 -> 1029.925 | AC19: 0.1 | AD19: =(N19-M19)*AC19 -> 324 | AE19: =17.5 -> 17.5 | AF19: =N19-M19-Q19-AB19-AD19-AE19 -> 1853.575 | AG19: =AF19/N19 -> 0.28516538 | AH19: =N19-AB19-AI19 -> 5340.4 | AI19: =Y19*N19 -> 129.675 | AJ19: 0.0085 | AK19: =AJ19*N19 -> 55.25
A20: 46059 | B20: 8583 - 8584 - 8585 - 8586 - 8587 | D20: BETIM | E20: MG | F20: GOIANIA | G20: GO | H20: UNIFORT | I20: FINALIZADO | J20: SIM | K20: LUIZ FELIPE DA SILVA | M20: 5060 | N20: 8200 | O20: 150000 | P20: 0.0003 | Q20: =O20*P20 -> 45 | R20: 0.03 | T20: 0.035 | U20: 1 | V20: =T20*N20 -> 287 | W20: 0.065 | X20: =N20*W20 -> 533 | Y20: =Z20*0.00133 -> 0.01995 | Z20: 15 | AA20: =R20+T20+W20+Y20 -> 0.14995 | AB20: =N20*AA20+AK20 -> 1299.29 | AC20: 0.1 | AD20: =(N20-M20)*AC20 -> 314 | AE20: =17.5 -> 17.5 | AF20: =N20-M20-Q20-AB20-AD20-AE20 -> 1464.21 | AG20: =AF20/N20 -> 0.1785622 | AH20: =N20-AB20-AI20 -> 6737.12 | AI20: =Y20*N20 -> 163.59 | AJ20: 0.0085 | AK20: =AJ20*N20 -> 69.7
A21: 46060 | B21: 8593 | D21: MARABA | E21: PA | F21: GOIANIA | G21: GO | H21: UNIFORT | I21: FINALIZADO | J21: SIM | K21: RAFAEL CORREA | M21: 7530 | N21: 11600 | O21: 100000 | P21: 0.0003 | Q21: =O21*P21 -> 30 | R21: 0.03 | T21: 0.035 | U21: 1 | V21: =T21*N21 -> 406 | W21: 0.065 | X21: =N21*W21 -> 754 | Y21: =Z21*0.00133 -> 0.01995 | Z21: 15 | AA21: =R21+T21+W21+Y21 -> 0.14995 | AB21: =N21*AA21+AK21 -> 1838.02 | AC21: 0.1 | AD21: =(N21-M21)*AC21 -> 407 | AE21: =17.5 -> 17.5 | AF21: =N21-M21-Q21-AB21-AD21-AE21 -> 1777.48 | AG21: =AF21/N21 -> 0.15323103 | AH21: =N21-AB21-AI21 -> 9530.56 | AI21: =Y21*N21 -> 231.42 | AJ21: 0.0085 | AK21: =AJ21*N21 -> 98.6
A22: 46061 | B22: 8597 - 8598 - 8599 - 8600 - 8601 - 8602 | D22: GOIANIA | E22: GO | F22: MARABA | G22: PA | H22: UNIFORT | I22: FINALIZADO | J22: SIM | K22: WILSON RODRIGUES | M22: 6710 | N22: 12900 | O22: 50000 | P22: 0.0003 | Q22: =O22*P22 -> 15 | R22: 0.03 | T22: 0.035 | U22: 1 | V22: =T22*N22 -> 451.5 | W22: 0.065 | X22: =N22*W22 -> 838.5 | Y22: =Z22*0.00133 -> 0.01995 | Z22: 15 | AA22: =R22+T22+W22+Y22 -> 0.14995 | AB22: =N22*AA22+AK22 -> 2044.005 | AC22: 0.1 | AD22: =(N22-M22)*AC22 -> 619 | AE22: =17.5 -> 17.5 | AF22: =N22-M22-Q22-AB22-AD22-AE22 -> 3494.495 | AG22: =AF22/N22 -> 0.27089109 | AH22: =N22-AB22-AI22 -> 10598.64 | AI22: =Y22*N22 -> 257.355 | AJ22: 0.0085 | AK22: =AJ22*N22 -> 109.65
A23: 46062 | B23: 8625 8626 8627 8628 | D23: GOIANIA | E23: GO | F23: VARZEA GRANDE | G23: MT | H23: UNIFORT | I23: FINALIZADO | J23: SIM | K23: JOSE VICENTE DA SILVA | M23: =5025.83+60 -> 5085.83 | N23: 8500 | O23: 50000 | P23: 0.0003 | Q23: =O23*P23 -> 15 | R23: 0.03 | T23: 0.035 | U23: 1 | V23: =T23*N23 -> 297.5 | W23: 0.065 | X23: =N23*W23 -> 552.5 | Y23: =Z23*0.00133 -> 0.01995 | Z23: 15 | AA23: =R23+T23+W23+Y23 -> 0.14995 | AB23: =N23*AA23+AK23 -> 1346.825 | AC23: 0.1 | AD23: =(N23-M23)*AC23 -> 341.417 | AE23: =17.5 -> 17.5 | AF23: =N23-M23-Q23-AB23-AD23-AE23 -> 1693.428 | AG23: =AF23/N23 -> 0.19922682 | AH23: =N23-AB23-AI23 -> 6983.6 | AI23: =Y23*N23 -> 169.575 | AJ23: 0.0085 | AK23: =AJ23*N23 -> 72.25
A24: 46062 | B24: 8617 8618 | D24: GUARULHOS | E24: SP | F24: SAO PAULO | G24: SP | H24: CYA RUBBER | I24: FINALIZADO | J24: SIM | K24: EDI LAZARO GONCALVES | M24: 960 | N24: 1630 | O24: 100000 | P24: 0.0003 | Q24: =O24*P24 -> 30 | R24: 0.12 | T24: 0 | U24: 1 | V24: =T24*N24 -> 0 | W24: 0.065 | X24: =N24*W24 -> 105.95 | Y24: =Z24*0.00133 -> 0.01995 | Z24: 15 | AA24: =R24+T24+W24+Y24 -> 0.20495 | AB24: =N24*AA24+AK24 -> 347.9235 | AC24: 0.07 | AD24: =(N24-M24)*AC24 -> 46.9 | AE24: =17.5 -> 17.5 | AF24: =N24-M24-Q24-AB24-AD24-AE24 -> 227.6765 | AG24: =AF24/N24 -> 0.13967883 | AH24: =N24-AB24-AI24 -> 1249.558 | AI24: =Y24*N24 -> 32.5185 | AJ24: 0.0085 | AK24: =AJ24*N24 -> 13.855
A25: 46062 | B25: 8644 | D25: ROCA SALES | E25: RS | F25: SÃO LEOPOLDO | G25: RS | H25: QUISVI | I25: FINALIZADO | J25: SIM | K25: CELSO LERMEN | M25: 1260 | N25: 2100 | O25: 80000 | P25: 0.0003 | Q25: =O25*P25 -> 24 | R25: 0 | T25: 0.035 | U25: 1 | V25: =T25*N25 -> 73.5 | W25: 0.065 | X25: =N25*W25 -> 136.5 | Y25: =Z25*0.00133 -> 0.01995 | Z25: 15 | AA25: =R25+T25+W25+Y25 -> 0.11995 | AB25: =N25*AA25+AK25 -> 269.745 | AC25: 0.13 | AD25: =(N25-M25)*AC25 -> 109.2 | AE25: =17.5 -> 17.5 | AF25: =N25-M25-Q25-AB25-AD25-AE25 -> 419.555 | AG25: =AF25/N25 -> 0.1997881 | AH25: =N25-AB25-AI25 -> 1788.36 | AI25: =Y25*N25 -> 41.895 | AJ25: 0.0085 | AK25: =AJ25*N25 -> 17.85
A26: 46063 | B26: 8652 | D26: GUARULHOS | E26: SP | F26: SALTO | G26: SP | H26: CYA RUBBER | I26: FINALIZADO | J26: SIM | K26: AGNALDO | M26: 1060 | N26: 2100 | O26: 50000 | P26: 0.0003 | Q26: =O26*P26 -> 15 | R26: 0.12 | T26: 0 | U26: 1 | V26: =T26*N26 -> 0 | W26: 0.065 | X26: =N26*W26 -> 136.5 | Y26: =Z26*0.00133 -> 0.01995 | Z26: 15 | AA26: =R26+T26+W26+Y26 -> 0.20495 | AB26: =N26*AA26+AK26 -> 448.245 | AC26: 0.13 | AD26: =(N26-M26)*AC26 -> 135.2 | AE26: =17.5 -> 17.5 | AF26: =N26-M26-Q26-AB26-AD26-AE26 -> 424.055 | AG26: =AF26/N26 -> 0.20193095 | AH26: =N26-AB26-AI26 -> 1609.86 | AI26: =Y26*N26 -> 41.895 | AJ26: 0.0085 | AK26: =AJ26*N26 -> 17.85
A27: 46063 | B27: 8658 | D27: GUARULHOS | E27: SP | F27: DIADEMA | G27: SP | H27: CYA RUBBER | I27: FINALIZADO | J27: SIM | K27: EMERSON NUNES | M27: 610 | N27: 1200 | O27: 50000 | P27: 0.0003 | Q27: =O27*P27 -> 15 | R27: 0.12 | T27: 0 | U27: 1 | V27: =T27*N27 -> 0 | W27: 0.065 | X27: =N27*W27 -> 78 | Y27: =Z27*0.00133 -> 0.01995 | Z27: 15 | AA27: =R27+T27+W27+Y27 -> 0.20495 | AB27: =N27*AA27+AK27 -> 256.14 | AC27: 0.13 | AD27: =(N27-M27)*AC27 -> 76.7 | AE27: =17.5 -> 17.5 | AF27: =N27-M27-Q27-AB27-AD27-AE27 -> 224.66 | AG27: =AF27/N27 -> 0.18721667 | AH27: =N27-AB27-AI27 -> 919.92 | AI27: =Y27*N27 -> 23.94 | AJ27: 0.0085 | AK27: =AJ27*N27 -> 10.2
A28: 46064 | B28: 8698 | D28: SAO LEOPOLDO | E28: RS | F28: BOM PRINCIPIO | G28: RS | H28: CYA RUBBER | I28: FINALIZADO | J28: SIM | K28: SERGIO CERVELLIN | M28: 960 | N28: 1550 | O28: 100000 | P28: 0.0003 | Q28: =O28*P28 -> 30 | R28: 0 | T28: 0.035 | U28: 1 | V28: =T28*N28 -> 54.25 | W28: 0.065 | X28: =N28*W28 -> 100.75 | Y28: =Z28*0.00133 -> 0.01995 | Z28: 15 | AA28: =R28+T28+W28+Y28 -> 0.11995 | AB28: =N28*AA28+AK28 -> 199.0975 | AC28: 0.13 | AD28: =(N28-M28)*AC28 -> 76.7 | AE28: =17.5 -> 17.5 | AF28: =N28-M28-Q28-AB28-AD28-AE28 -> 266.7025 | AG28: =AF28/N28 -> 0.17206613 | AH28: =N28-AB28-AI28 -> 1319.98 | AI28: =Y28*N28 -> 30.9225 | AJ28: 0.0085 | AK28: =AJ28*N28 -> 13.175
A29: 46064 | B29: 8700 | D29: GUARULHOS | E29: SP | F29: GUARULHOS | G29: SP | H29: CYA RUBBER | I29: FINALIZADO | J29: SIM | K29: AGNALDO CICERO | M29: 460 | N29: 1050 | O29: 20000 | P29: 0.0003 | Q29: =O29*P29 -> 6 | R29: 0.12 | T29: 0 | U29: 1 | V29: =T29*N29 -> 0 | W29: 0.065 | X29: =N29*W29 -> 68.25 | Y29: =Z29*0.00133 -> 0.01995 | Z29: 15 | AA29: =R29+T29+W29+Y29 -> 0.20495 | AB29: =N29*AA29+AK29 -> 224.1225 | AC29: 0.13 | AD29: =(N29-M29)*AC29 -> 76.7 | AE29: =17.5 -> 17.5 | AF29: =N29-M29-Q29-AB29-AD29-AE29 -> 265.6775 | AG29: =AF29/N29 -> 0.25302619 | AH29: =N29-AB29-AI29 -> 804.93 | AI29: =Y29*N29 -> 20.9475 | AJ29: 0.0085 | AK29: =AJ29*N29 -> 8.925
A30: 46064 | B30: 8708 8709 | D30: VARZEA GRANDE | E30: MT | F30: VILHENA | G30: RO | H30: UNIFORT | I30: FINALIZADO | J30: SIM | K30: MIGUEL FERNANDO | M30: 3560 | N30: 5900 | O30: 30000 | P30: 0.0003 | Q30: =O30*P30 -> 9 | R30: 0.03 | T30: 0.035 | U30: 1 | V30: =T30*N30 -> 206.5 | W30: 0.065 | X30: =N30*W30 -> 383.5 | Y30: =Z30*0.00133 -> 0.01995 | Z30: 15 | AA30: =R30+T30+W30+Y30 -> 0.14995 | AB30: =N30*AA30+AK30 -> 934.855 | AC30: 0.1 | AD30: =(N30-M30)*AC30 -> 234 | AE30: =17.5 -> 17.5 | AF30: =N30-M30-Q30-AB30-AD30-AE30 -> 1144.645 | AG30: =AF30/N30 -> 0.19400763 | AH30: =N30-AB30-AI30 -> 4847.44 | AI30: =Y30*N30 -> 117.705 | AJ30: 0.0085 | AK30: =AJ30*N30 -> 50.15
A31: 46064 | B31: 8706 | D31: SÃO LEOPOLDO | E31: RS | F31: CAXIAS DO SUL | G31: RS | H31: CYA RUBBER | I31: FINALIZADO | J31: SIM | K31: SERGIO CERVELLIN | M31: 1150 | N31: 1750 | O31: 100000 | P31: 0.0003 | Q31: =O31*P31 -> 30 | R31: 0 | T31: 0.035 | U31: 1 | V31: =T31*N31 -> 61.25 | W31: 0.065 | X31: =N31*W31 -> 113.75 | Y31: =Z31*0.00133 -> 0.01995 | Z31: 15 | AA31: =R31+T31+W31+Y31 -> 0.11995 | AB31: =N31*AA31+AK31 -> 224.7875 | AC31: 0.1 | AD31: =(N31-M31)*AC31 -> 60 | AE31: =17.5 -> 17.5 | AF31: =N31-M31-Q31-AB31-AD31-AE31 -> 267.7125 | AG31: =AF31/N31 -> 0.15297857 | AH31: =N31-AB31-AI31 -> 1490.3 | AI31: =Y31*N31 -> 34.9125 | AJ31: 0.0085 | AK31: =AJ31*N31 -> 14.875
